<?xml version="1.0"?>
<sdf version='1.4'>
  <model name='atlas'>
    <link name='pelvis'>
      <inertial>
        <pose>0.0113715 0 -1.0268706 0 -0 0</pose>
        <mass>100.7982</mass>
        <inertia>
          <ixx>0.125569</ixx>
          <ixy>0.0008</ixy>
          <ixz>-0.000499757</ixz>
          <iyy>0.0972062</iyy>
          <iyz>-0.0005</iyz>
          <izz>0.117937</izz>
        </inertia>
      </inertial>
      <visual name='utorso_visual'>
      <pose>-0.0125 0 0.21197 0 -0 0</pose>
        <geometry>
          <mesh>
            <scale>1 1 1</scale>
            <uri>model://atlas_hydra/meshes/utorso.DAE</uri>
          </mesh>
        </geometry>
      </visual>
      <visual name='utorso_visual_utorso_1'>
      <pose>-0.0125 0 0.21197 0 -0 0</pose>
        <geometry>
          <mesh>
            <scale>1 1 1</scale>
            <uri>model://atlas_hydra/meshes/utorso_pack.DAE</uri>
          </mesh>
        </geometry>
      </visual>

      <!--
      <collision name='pelvis_collision'>
        <geometry>
          <mesh>
            <scale>1 1 1</scale>
            <uri>model://atlas_hydra/meshes/pelvis.DAE</uri>
          </mesh>
        </geometry>
        <surface>
          <friction>
            <ode>
              <mu>0.9</mu>
              <mu2>0.9</mu2>
            </ode>
          </friction>
        </surface>
      </collision>
-->
      <visual name='head_visual'>
      <pose>0.20422 0 0.74993 0 -0 0</pose>
        <geometry>
          <mesh>
            <scale>1 1 1</scale>
            <uri>model://multisense_sl/meshes/head.dae</uri>
          </mesh>
        </geometry>
      </visual>
      <visual name='l_uglut_visual'>
      <pose>0 0.089 0 0 -0 0</pose>
        <geometry>
          <mesh>
            <scale>1 1 1</scale>
            <uri>model://atlas_hydra/meshes/l_uglut.DAE</uri>
          </mesh>
        </geometry>
      </visual>
      <visual name='l_lglut_visual'>
      <pose>0 0.089 0 0 -0 0</pose>
        <geometry>
          <mesh>
            <scale>1 1 1</scale>
            <uri>model://atlas_hydra/meshes/l_lglut.DAE</uri>
          </mesh>
        </geometry>
      </visual>
      <visual name='l_uleg_visual'>
        <pose>0.05 0.089 -0.05 0 -0 0</pose>
        <geometry>
          <mesh>
            <scale>1 1 1</scale>
            <uri>model://atlas_hydra/meshes/l_uleg.DAE</uri>
          </mesh>
        </geometry>
      </visual>
      <visual name='l_lleg_visual'>
        <pose>0 0.089 -0.424 0 -0 0</pose>
        <geometry>
          <mesh>
            <scale>1 1 1</scale>
            <uri>model://atlas_hydra/meshes/l_lleg.DAE</uri>
          </mesh>
        </geometry>
      </visual>
      <visual name='l_talus_visual'>
        <pose>0 0.089 -0.846 0 -0 0</pose>
        <geometry>
          <mesh>
            <scale>1 1 1</scale>
            <uri>model://atlas_hydra/meshes/l_talus.DAE</uri>
          </mesh>
        </geometry>
      </visual>
      <visual name='l_foot_visual'>
        <pose>0 0.089 -0.846 0 -0 0</pose>
        <geometry>
          <mesh>
            <scale>1 1 1</scale>
            <uri>model://atlas_hydra/meshes/l_foot.DAE</uri>
          </mesh>
        </geometry>
      </visual>

      <visual name='r_uglut_visual'>
        <pose>0 -0.089 0 0 -0 0</pose>
        <geometry>
          <mesh>
            <scale>1 1 1</scale>
            <uri>model://atlas_hydra/meshes/r_uglut.DAE</uri>
          </mesh>
        </geometry>
      </visual>
      <visual name='r_lglut_visual'>
        <pose>0 -0.089 0 0 -0 0</pose>
        <geometry>
          <mesh>
            <scale>1 1 1</scale>
            <uri>model://atlas_hydra/meshes/r_lglut.DAE</uri>
          </mesh>
        </geometry>
      </visual>
      <visual name='r_uleg_visual'>
        <pose>0.05 -0.089 -0.05 0 -0 0</pose>
        <geometry>
          <mesh>
            <scale>1 1 1</scale>
            <uri>model://atlas_hydra/meshes/r_uleg.DAE</uri>
          </mesh>
        </geometry>
      </visual>
      <visual name='r_lleg_visual'>
        <pose>0 -0.089 -0.424 0 -0 0</pose>
        <geometry>
          <mesh>
            <scale>1 1 1</scale>
            <uri>model://atlas_hydra/meshes/r_lleg.DAE</uri>
          </mesh>
        </geometry>
      </visual>
      <visual name='r_talus_visual'>
        <pose>0 -0.089 -0.846 0 -0 0</pose>
        <geometry>
          <mesh>
            <scale>1 1 1</scale>
            <uri>model://atlas_hydra/meshes/r_talus.DAE</uri>
          </mesh>
        </geometry>
      </visual>
      <visual name='r_foot_visual'>
        <pose>0 -0.089 -0.846 0 -0 0</pose>
        <geometry>
          <mesh>
            <scale>1 1 1</scale>
            <uri>model://atlas_hydra/meshes/r_foot.DAE</uri>
          </mesh>
        </geometry>
      </visual>



      <visual name='pelvis_visual'>
        <geometry>
          <mesh>
            <scale>1 1 1</scale>
            <uri>model://atlas_hydra/meshes/pelvis.DAE</uri>
          </mesh>
        </geometry>
      </visual>
      <visual name='pelvis_visual_imu_link'>
        <pose>0.0599153 0 -0.01415 0 -0 0</pose>
        <geometry>
          <box>
            <size>0.01 0.01 0.01</size>
          </box>
        </geometry>
      </visual>
      <!--
    </link>
    <link name='ltorso'>
      <pose>-0.0125 0 0 0 -0 0</pose>
      <inertial>
        <pose>-0.0112984 -3.15366e-06 0.0746835 0 -0 0</pose>
        <mass>.2409</mass>
        <inertia>
          <ixx>0.0039092</ixx>
          <ixy>-5.04491e-08</ixy>
          <ixz>-0.000342157</ixz>
          <iyy>0.00341694</iyy>
          <iyz>4.87119e-07</iyz>
          <izz>0.00174492</izz>
        </inertia>
      </inertial>
      <collision name='ltorso_collision'>
        <pose>0 0 0 0 -0 0</pose>
        <geometry>
          <mesh>
            <scale>1 1 1</scale>
            <uri>model://atlas_hydra/meshes/ltorso.DAE</uri>
          </mesh>
        </geometry>
        <surface>
          <contact>
            <ode/>
          </contact>
          <friction>
            <ode>
              <mu>0.9</mu>
              <mu2>0.9</mu2>
            </ode>
          </friction>
        </surface>
      </collision>
-->
      <visual name='ltorso_visual'>
      <pose>-0.0125 0 0 0 -0 0</pose>
        <geometry>
          <mesh>
            <scale>1 1 1</scale>
            <uri>model://atlas_hydra/meshes/ltorso.DAE</uri>
          </mesh>
        </geometry>
      </visual>
    <!--
    </link>
    <joint name='back_bkz' type='revolute'>
      <child>ltorso</child>
      <parent>pelvis</parent>
      <axis>
        <xyz>0 0 1</xyz>
        <limit>
          <lower>0</lower>
          <upper>0</upper>
          <effort>124.016</effort>
          <velocity>12</velocity>
        </limit>
        <dynamics>
          <damping>0.1</damping>
        </dynamics>
      </axis>
      <physics>
        <ode>
          <implicit_spring_damper>1</implicit_spring_damper>
          <limit>
            <cfm>0</cfm>
            <erp>0.2</erp>
          </limit>
        </ode>
      </physics>
    </joint>
    <link name='mtorso'>
      <pose>-0.0125 0 0.16197 0 -0 0</pose>
      <inertial>
        <pose>-0.00816266 -0.0131245 0.0305974 0 -0 0</pose>
        <mass>0.069</mass>
        <inertia>
          <ixx>0.000454181</ixx>
          <ixy>-6.10764e-05</ixy>
          <ixz>3.94009e-05</ixz>
          <iyy>0.000483282</iyy>
          <iyz>5.27463e-05</iyz>
          <izz>0.000444215</izz>
        </inertia>
      </inertial>
      <collision name='mtorso_collision'>
        <pose>0 0 0 0 -0 0</pose>
        <geometry>
          <mesh>
            <scale>1 1 1</scale>
            <uri>model://atlas_hydra/meshes/mtorso.DAE</uri>
          </mesh>
        </geometry>
        <surface>
          <contact>
            <ode/>
          </contact>
          <friction>
            <ode>
              <mu>0.9</mu>
              <mu2>0.9</mu2>
            </ode>
          </friction>
        </surface>
      </collision>
-->
      <visual name='mtorso_visual'>
        <pose>-0.0125 0 0.16197 0 -0 0</pose>
        <geometry>
          <mesh>
            <scale>1 1 1</scale>
            <uri>model://atlas_hydra/meshes/mtorso.DAE</uri>
          </mesh>
        </geometry>
      </visual>
    </link>
    <!--
    <joint name='back_bky' type='revolute'>
      <child>mtorso</child>
      <parent>ltorso</parent>
      <axis>
        <xyz>0 1 0</xyz>
        <limit>
          <lower>0</lower>
          <upper>0</upper>
          <effort>206.843</effort>
          <velocity>12</velocity>
        </limit>
        <dynamics>
          <damping>0.1</damping>
        </dynamics>
      </axis>
      <physics>
        <ode>
          <implicit_spring_damper>1</implicit_spring_damper>
          <limit>
            <cfm>0</cfm>
            <erp>0.2</erp>
          </limit>
        </ode>
      </physics>
    </joint>
    <link name='utorso'>
      <pose>-0.0125 0 0.21197 0 -0 0</pose>
      <inertial>
        <pose>-0.0911174 0 0.300409 0 -0 0</pose>
        <mass>5.2207</mass>
        <inertia>
          <ixx>1.47126</ixx>
          <ixy>0.00362</ixy>
          <ixz>0.329434</ixz>
          <iyy>1.53128</iyy>
          <iyz>0.001</iyz>
          <izz>1.32197</izz>
        </inertia>
      </inertial>
      <visual name='utorso_visual'>
      <pose>-0.0125 0 0.21197 0 -0 0</pose>
        <geometry>
          <mesh>
            <scale>1 1 1</scale>
            <uri>model://atlas_hydra/meshes/utorso.DAE</uri>
          </mesh>
        </geometry>
      </visual>
      <visual name='utorso_visual_utorso_1'>
      <pose>-0.0125 0 0.21197 0 -0 0</pose>
        <geometry>
          <mesh>
            <scale>1 1 1</scale>
            <uri>model://atlas_hydra/meshes/utorso_pack.DAE</uri>
          </mesh>
        </geometry>
      </visual>
      <visual name='utorso_visual_l_situational_awareness_camera_link'>
        <pose>0.216409 0.121799 0.406759 -1.5708 5.55112e-17 1.309</pose>
        <geometry>
          <box>
            <size>0.01 0.01 0.01</size>
          </box>
        </geometry>
      </visual>
      <visual name='utorso_visual_r_situational_awareness_camera_link'>
        <pose>0.216409 -0.121799 0.406759 1.5708 5.55112e-17 -1.309</pose>
        <geometry>
          <box>
            <size>0.01 0.01 0.01</size>
          </box>
        </geometry>
      </visual>
    </link>
    <joint name='back_bkx' type='revolute'>
      <child>utorso</child>
      <parent>pelvis</parent>
      <axis>
        <xyz>1 0 0</xyz>
        <limit>
          <lower>0</lower>
          <upper>0</upper>
          <effort>200</effort>
          <velocity>12</velocity>
        </limit>
        <dynamics>
          <damping>0.1</damping>
        </dynamics>
      </axis>
      <physics>
        <ode>
          <implicit_spring_damper>1</implicit_spring_damper>
          <limit>
            <cfm>0</cfm>
            <erp>0.2</erp>
          </limit>
        </ode>
      </physics>
    </joint>
-->
    <link name='l_clav'>
      <pose>0.05191 0.13866 0.31915 0 -0 0</pose>
      <inertial>
        <pose>0 0.048 0.084 0 -0 0</pose>
        <mass>.345</mass>
        <inertia>
          <ixx>0.011</ixx>
          <ixy>0</ixy>
          <ixz>0</ixz>
          <iyy>0.009</iyy>
          <iyz>-0.004</iyz>
          <izz>0.004</izz>
        </inertia>
      </inertial>
      <!--
      <collision name='l_clav_collision'>
        <pose>0 0 0 0 -0 0</pose>
        <geometry>
          <mesh>
            <scale>1 1 1</scale>
            <uri>model://atlas_hydra/meshes/l_clav.DAE</uri>
          </mesh>
        </geometry>
        <surface>
          <contact>
            <ode/>
          </contact>
          <friction>
            <ode>
              <mu>0.9</mu>
              <mu2>0.9</mu2>
            </ode>
          </friction>
        </surface>
      </collision>
-->
      <visual name='l_clav_visual'>
        <pose>0 0 0 0 -0 0</pose>
        <geometry>
          <mesh>
            <scale>1 1 1</scale>
            <uri>model://atlas_hydra/meshes/l_clav.DAE</uri>
          </mesh>
        </geometry>
      </visual>
      <gravity>1</gravity>
      <velocity_decay>
        <linear>0</linear>
        <angular>0</angular>
      </velocity_decay>
      <self_collide>0</self_collide>
    </link>
    <joint name='l_arm_shy' type='revolute'>
      <child>l_clav</child>
      <parent>pelvis</parent>
      <axis>
        <xyz>0 0.5 0.866025</xyz>
        <limit>
          <!--
          <lower>-1.5708</lower>
          <upper>0.785398</upper>
-->
          <effort>212</effort>
          <velocity>12</velocity>
        </limit>
        <dynamics>
          <damping>0.1</damping>
        </dynamics>
      </axis>
      <physics>
        <ode>
          <implicit_spring_damper>1</implicit_spring_damper>
          <limit>
            <cfm>0</cfm>
            <erp>0.2</erp>
          </limit>
        </ode>
      </physics>
    </joint>
    <link name='l_scap'>
      <pose>0.05191 0.27901 0.51524 0 -0 0</pose>
      <inertial>
        <pose>0 0 0 0 -0 0</pose>
        <mass>.3012</mass>
        <inertia>
          <ixx>0.00319</ixx>
          <ixy>0</ixy>
          <ixz>0</ixz>
          <iyy>0.00583</iyy>
          <iyz>0</iyz>
          <izz>0.00583</izz>
        </inertia>
      </inertial>
      <!--
      <collision name='l_scap_collision'>
        <pose>0 0 0 0 -0 0</pose>
        <geometry>
          <mesh>
            <scale>1 1 1</scale>
            <uri>model://atlas_hydra/meshes/l_sh_rx.DAE</uri>
          </mesh>
        </geometry>
        <surface>
          <contact>
            <ode/>
          </contact>
          <friction>
            <ode>
              <mu>0.9</mu>
              <mu2>0.9</mu2>
            </ode>
          </friction>
        </surface>
      </collision>
-->
      <visual name='l_scap_visual'>
        <pose>0 0 0 0 -0 0</pose>
        <geometry>
          <mesh>
            <scale>1 1 1</scale>
            <uri>model://atlas_hydra/meshes/l_sh_rx.DAE</uri>
          </mesh>
        </geometry>
      </visual>
      <gravity>1</gravity>
      <velocity_decay>
        <linear>0</linear>
        <angular>0</angular>
      </velocity_decay>
      <self_collide>0</self_collide>
    </link>
    <joint name='l_arm_shx' type='revolute'>
      <child>l_scap</child>
      <parent>l_clav</parent>
      <axis>
        <xyz>1 0 0</xyz>
        <limit>
          <!--
          <lower>-1.5708</lower>
          <upper>1.5708</upper>
-->
          <effort>170</effort>
          <velocity>12</velocity>
        </limit>
        <dynamics>
          <damping>0.1</damping>
        </dynamics>
      </axis>
      <physics>
        <ode>
          <implicit_spring_damper>1</implicit_spring_damper>
          <limit>
            <cfm>0</cfm>
            <erp>0.2</erp>
          </limit>
        </ode>
      </physics>
    </joint>
    <link name='l_uarm'>
      <pose>0.05191 0.46601 0.53124 0 -0 0</pose>
      <inertial>
        <pose>0 -0.065 0 0 -0 0</pose>
        <mass>.3388</mass>
        <inertia>
          <ixx>0.00656</ixx>
          <ixy>0</ixy>
          <ixz>0</ixz>
          <iyy>0.00358</iyy>
          <iyz>0</iyz>
          <izz>0.00656</izz>
        </inertia>
      </inertial>
      <!--
      <collision name='l_uarm_collision'>
        <pose>0 0 0 0 -0 0</pose>
        <geometry>
          <mesh>
            <scale>1 1 1</scale>
            <uri>model://atlas_hydra/meshes/l_elbow_ry.DAE</uri>
          </mesh>
        </geometry>
        <surface>
          <contact>
            <ode/>
          </contact>
          <friction>
            <ode>
              <mu>0.9</mu>
              <mu2>0.9</mu2>
            </ode>
          </friction>
        </surface>
      </collision>
-->
      <visual name='l_uarm_visual'>
        <pose>0 0 0 0 -0 0</pose>
        <geometry>
          <mesh>
            <scale>1 1 1</scale>
            <uri>model://atlas_hydra/meshes/l_elbow_ry.DAE</uri>
          </mesh>
        </geometry>
      </visual>
      <gravity>1</gravity>
      <velocity_decay>
        <linear>0</linear>
        <angular>0</angular>
      </velocity_decay>
      <self_collide>0</self_collide>
    </link>
    <joint name='l_arm_ely' type='revolute'>
      <child>l_uarm</child>
      <parent>l_scap</parent>
      <axis>
        <xyz>0 1 0</xyz>
        <limit>
          <!--
          <lower>0</lower>
          <upper>3.14159</upper>
-->
          <effort>114</effort>
          <velocity>12</velocity>
        </limit>
        <dynamics>
          <damping>0.1</damping>
        </dynamics>
      </axis>
      <physics>
        <ode>
          <implicit_spring_damper>1</implicit_spring_damper>
          <limit>
            <cfm>0</cfm>
            <erp>0.2</erp>
          </limit>
        </ode>
      </physics>
    </joint>
    <link name='l_larm'>
      <pose>0.05191 0.58501 0.54045 0 -0 0</pose>
      <inertial>
        <pose>0 0 0 0 -0 0</pose>
        <mass>.2509</mass>
        <inertia>
          <ixx>0.00265</ixx>
          <ixy>0</ixy>
          <ixz>0</ixz>
          <iyy>0.00446</iyy>
          <iyz>0</iyz>
          <izz>0.00446</izz>
        </inertia>
      </inertial>
      <!--
      <collision name='l_larm_collision'>
        <pose>0 0 0 0 -0 0</pose>
        <geometry>
          <mesh>
            <scale>1 1 1</scale>
            <uri>model://atlas_hydra/meshes/l_elbow_rx.DAE</uri>
          </mesh>
        </geometry>
        <surface>
          <contact>
            <ode/>
          </contact>
          <friction>
            <ode>
              <mu>0.9</mu>
              <mu2>0.9</mu2>
            </ode>
          </friction>
        </surface>
      </collision>
-->
      <visual name='l_larm_visual'>
        <pose>0 0 0 0 -0 0</pose>
        <geometry>
          <mesh>
            <scale>1 1 1</scale>
            <uri>model://atlas_hydra/meshes/l_elbow_rx.DAE</uri>
          </mesh>
        </geometry>
      </visual>
      <gravity>1</gravity>
      <velocity_decay>
        <linear>0</linear>
        <angular>0</angular>
      </velocity_decay>
      <self_collide>0</self_collide>
    </link>
    <joint name='l_arm_elx' type='revolute'>
      <child>l_larm</child>
      <parent>l_uarm</parent>
      <axis>
        <xyz>1 0 0</xyz>
        <limit>
          <!--
          <lower>0</lower>
          <upper>2.35619</upper>
-->
          <effort>114</effort>
          <velocity>12</velocity>
        </limit>
        <dynamics>
          <damping>0.1</damping>
        </dynamics>
      </axis>
      <physics>
        <ode>
          <implicit_spring_damper>1</implicit_spring_damper>
          <limit>
            <cfm>0</cfm>
            <erp>0.2</erp>
          </limit>
        </ode>
      </physics>
    </joint>
    <link name='l_farm'>
      <pose>0.05191 0.77201 0.53124 0 -0 0</pose>
      <inertial>
        <pose>0 -0.065 0 0 -0 0</pose>
        <mass>.3388</mass>
        <inertia>
          <ixx>0.00656</ixx>
          <ixy>0</ixy>
          <ixz>0</ixz>
          <iyy>0.00358</iyy>
          <iyz>0</iyz>
          <izz>0.00656</izz>
        </inertia>
      </inertial>
      <!--
      <collision name='l_farm_collision'>
        <pose>0 0 0 0 -0 0</pose>
        <geometry>
          <mesh>
            <scale>1 1 1</scale>
            <uri>model://atlas_hydra/meshes/l_farm.DAE</uri>
          </mesh>
        </geometry>
        <surface>
          <contact>
            <ode/>
          </contact>
          <friction>
            <ode>
              <mu>0.9</mu>
              <mu2>0.9</mu2>
            </ode>
          </friction>
        </surface>
      </collision>
-->
      <visual name='l_farm_visual'>
        <pose>0 0 0 0 -0 0</pose>
        <geometry>
          <mesh>
            <scale>1 1 1</scale>
            <uri>model://atlas_hydra/meshes/l_farm.DAE</uri>
          </mesh>
        </geometry>
      </visual>
      <gravity>1</gravity>
      <velocity_decay>
        <linear>0</linear>
        <angular>0</angular>
      </velocity_decay>
      <self_collide>0</self_collide>
    </link>
    <joint name='l_arm_wry' type='revolute'>
      <child>l_farm</child>
      <parent>l_larm</parent>
      <axis>
        <xyz>0 1 0</xyz>
        <limit>
          <!--
          <lower>0</lower>
          <upper>3.14159</upper>
-->
          <effort>114</effort>
          <velocity>12</velocity>
        </limit>
        <dynamics>
          <damping>0.1</damping>
        </dynamics>
      </axis>
      <physics>
        <ode>
          <implicit_spring_damper>1</implicit_spring_damper>
          <limit>
            <cfm>0</cfm>
            <erp>0.2</erp>
          </limit>
        </ode>
      </physics>
    </joint>
    <link name='l_hand'>
      <pose>0.05191 0.89101 0.54045 0 -0 0</pose>
      <inertial>
        <pose>0.0035582 0.0860336 0.00645092 0 -0 0</pose>
        <mass>.4872</mass>
        <inertia>
          <ixx>0.049418</ixx>
          <ixy>-0.0029244</ixy>
          <ixz>2.43235e-05</ixz>
          <iyy>0.00805204</iyy>
          <iyz>-0.00287073</iyz>
          <izz>0.0527048</izz>
        </inertia>
      </inertial>
      <collision name='l_hand_collision'>
        <pose>0 0 0 0 -0 0</pose>
        <geometry>
          <mesh>
            <scale>1 1 1</scale>
            <uri>model://atlas_hydra/meshes/l_hand.DAE</uri>
          </mesh>
        </geometry>
        <surface>
          <contact>
            <ode/>
          </contact>
          <friction>
            <ode/>
          </friction>
        </surface>
        <surface>
          <contact>
            <ode/>
          </contact>
          <friction>
            <ode>
              <mu>0.9</mu>
              <mu2>0.9</mu2>
            </ode>
          </friction>
        </surface>
      </collision>
      <collision name='l_hand_collision_left_palm'>
        <pose>0.0177904 0.20416 0.04976 -3.14157 1.57079 -0.670783</pose>
        <geometry>
          <cylinder>
            <length>0.1</length>
            <radius>0.013</radius>
          </cylinder>
        </geometry>
        <surface>
          <contact>
            <ode/>
          </contact>
          <friction>
            <ode/>
          </friction>
        </surface>
        <surface>
          <contact>
            <ode/>
          </contact>
          <friction>
            <ode>
              <mu>0.9</mu>
              <mu2>0.9</mu2>
            </ode>
          </friction>
        </surface>
        <max_contacts>6</max_contacts>
        <surface>
          <contact>
            <ode>
              <kp>1e+06</kp>
              <kd>1</kd>
              <max_vel>0.01</max_vel>
              <min_depth>0</min_depth>
            </ode>
          </contact>
          <friction>
            <ode>
              <mu>1.1</mu>
              <mu2>1.1</mu2>
            </ode>
          </friction>
        </surface>
      </collision>
      <collision name='l_hand_collision_left_palm_1'>
        <pose>0.0097904 0.19916 0.03276 -0.41 2.77556e-17 2.47079</pose>
        <geometry>
          <box>
            <size>0.09 0.035 0.05</size>
          </box>
        </geometry>
        <surface>
          <contact>
            <ode/>
          </contact>
          <friction>
            <ode/>
          </friction>
        </surface>
        <surface>
          <contact>
            <ode/>
          </contact>
          <friction>
            <ode>
              <mu>0.9</mu>
              <mu2>0.9</mu2>
            </ode>
          </friction>
        </surface>
      </collision>
      <collision name='l_hand_collision_left_palm_2'>
        <pose>0.00179013 0.15516 0.00676 3.14158 1.57079 -1.57082</pose>
        <geometry>
          <cylinder>
            <length>0.05</length>
            <radius>0.038</radius>
          </cylinder>
        </geometry>
        <surface>
          <contact>
            <ode/>
          </contact>
          <friction>
            <ode/>
          </friction>
        </surface>
        <surface>
          <contact>
            <ode/>
          </contact>
          <friction>
            <ode>
              <mu>0.9</mu>
              <mu2>0.9</mu2>
            </ode>
          </friction>
        </surface>
      </collision>
      <collision name='l_hand_collision_left_palm_3'>
        <pose>-0.0082093 0.24516 0.00676 0 -0 1.20079</pose>
        <geometry>
          <box>
            <size>0.09 0.03 0.06</size>
          </box>
        </geometry>
        <surface>
          <contact>
            <ode/>
          </contact>
          <friction>
            <ode/>
          </friction>
        </surface>
        <surface>
          <contact>
            <ode/>
          </contact>
          <friction>
            <ode>
              <mu>0.9</mu>
              <mu2>0.9</mu2>
            </ode>
          </friction>
        </surface>
      </collision>
      <collision name='l_hand_collision_left_palm_4'>
        <pose>0.0217906 0.22516 0.00676 0 -0 1.20079</pose>
        <geometry>
          <box>
            <size>0.09 0.03 0.06</size>
          </box>
        </geometry>
        <surface>
          <contact>
            <ode/>
          </contact>
          <friction>
            <ode/>
          </friction>
        </surface>
        <surface>
          <contact>
            <ode/>
          </contact>
          <friction>
            <ode>
              <mu>0.9</mu>
              <mu2>0.9</mu2>
            </ode>
          </friction>
        </surface>
      </collision>
      <collision name='l_hand_collision_left_palm_5'>
        <pose>0.0517904 0.19516 0.00676 0 -0 1.20079</pose>
        <geometry>
          <box>
            <size>0.09 0.03 0.06</size>
          </box>
        </geometry>
        <surface>
          <contact>
            <ode/>
          </contact>
          <friction>
            <ode/>
          </friction>
        </surface>
        <surface>
          <contact>
            <ode/>
          </contact>
          <friction>
            <ode>
              <mu>0.9</mu>
              <mu2>0.9</mu2>
            </ode>
          </friction>
        </surface>
      </collision>
      <collision name='l_hand_collision_left_palm_6'>
        <pose>-0.0382097 0.17916 0.00676 0 -0 0.78079</pose>
        <geometry>
          <box>
            <size>0.09 0.03 0.06</size>
          </box>
        </geometry>
        <surface>
          <contact>
            <ode/>
          </contact>
          <friction>
            <ode/>
          </friction>
        </surface>
        <surface>
          <contact>
            <ode/>
          </contact>
          <friction>
            <ode>
              <mu>0.9</mu>
              <mu2>0.9</mu2>
            </ode>
          </friction>
        </surface>
      </collision>
      <visual name='l_hand_visual'>
        <pose>0 0 0 0 -0 0</pose>
        <geometry>
          <mesh>
            <scale>1 1 1</scale>
            <uri>model://atlas_hydra/meshes/l_hand.DAE</uri>
          </mesh>
        </geometry>
      </visual>
      <visual name='l_hand_visual_left_palm'>
        <pose>0.0177904 0.20416 0.04976 -3.14157 1.57079 -0.670783</pose>
        <geometry>
          <cylinder>
            <length>0.1</length>
            <radius>0.013</radius>
          </cylinder>
        </geometry>
        <material>
          <script>
            <name>Gazebo/FlatBlack</name>
            <uri>__default__</uri>
          </script>
        </material>
      </visual>
      <visual name='l_hand_visual_left_palm_1'>
        <pose>0.0097904 0.19916 0.03276 -0.41 2.77556e-17 2.47079</pose>
        <geometry>
          <box>
            <size>0.09 0.035 0.05</size>
          </box>
        </geometry>
        <material>
          <script>
            <name>Gazebo/FlatBlack</name>
            <uri>__default__</uri>
          </script>
        </material>
      </visual>
      <visual name='l_hand_visual_left_palm_2'>
        <pose>0.00179013 0.15516 0.00676 3.14158 1.57079 -1.57082</pose>
        <geometry>
          <cylinder>
            <length>0.05</length>
            <radius>0.038</radius>
          </cylinder>
        </geometry>
        <material>
          <script>
            <name>Gazebo/FlatBlack</name>
            <uri>__default__</uri>
          </script>
        </material>
      </visual>
      <visual name='l_hand_visual_left_palm_3'>
        <pose>-0.0082093 0.24516 0.00676 0 -0 1.20079</pose>
        <geometry>
          <box>
            <size>0.09 0.03 0.06</size>
          </box>
        </geometry>
        <material>
          <script>
            <name>Gazebo/FlatBlack</name>
            <uri>__default__</uri>
          </script>
        </material>
      </visual>
      <visual name='l_hand_visual_left_palm_4'>
        <pose>0.0217906 0.22516 0.00676 0 -0 1.20079</pose>
        <geometry>
          <box>
            <size>0.09 0.03 0.06</size>
          </box>
        </geometry>
        <material>
          <script>
            <name>Gazebo/FlatBlack</name>
            <uri>__default__</uri>
          </script>
        </material>
      </visual>
      <visual name='l_hand_visual_left_palm_5'>
        <pose>0.0517904 0.19516 0.00676 0 -0 1.20079</pose>
        <geometry>
          <box>
            <size>0.09 0.03 0.06</size>
          </box>
        </geometry>
        <material>
          <script>
            <name>Gazebo/FlatBlack</name>
            <uri>__default__</uri>
          </script>
        </material>
      </visual>
      <visual name='l_hand_visual_left_palm_6'>
        <pose>-0.0382097 0.17916 0.00676 0 -0 0.78079</pose>
        <geometry>
          <box>
            <size>0.09 0.03 0.06</size>
          </box>
        </geometry>
        <material>
          <script>
            <name>Gazebo/FlatBlack</name>
            <uri>__default__</uri>
          </script>
        </material>
      </visual>
      <visual name='l_hand_visual_left_palm_left_camera_frame'>
        <pose>0.0469576 0.178673 0.03676 2.47075 -1.57079 1.57083</pose>
        <geometry>
          <box>
            <size>0.003 0.01 0.007</size>
          </box>
        </geometry>
        <material>
          <script>
            <name>Gazebo/FlatBlack</name>
            <uri>__default__</uri>
          </script>
        </material>
      </visual>
      <visual name='l_hand_visual_left_palm_right_camera_frame'>
        <pose>0.0156247 0.203537 0.03676 2.47075 -1.57079 1.57083</pose>
        <geometry>
          <box>
            <size>0.003 0.01 0.007</size>
          </box>
        </geometry>
        <material>
          <script>
            <name>Gazebo/FlatBlack</name>
            <uri>__default__</uri>
          </script>
        </material>
      </visual>
      <velocity_decay>
        <linear>0</linear>
        <angular>0</angular>
      </velocity_decay>
    </link>
    <joint name='l_arm_wrx' type='revolute'>
      <child>l_hand</child>
      <parent>l_farm</parent>
      <axis>
        <xyz>1 0 0</xyz>
        <limit>
          <!--
          <lower>-1.1781</lower>
          <upper>1.1781</upper>
-->
          <effort>60</effort>
          <velocity>12</velocity>
        </limit>
        <dynamics>
          <damping>0.1</damping>
        </dynamics>
      </axis>
      <physics>
        <provide_feedback>1</provide_feedback>
        <ode>
          <provide_feedback>1</provide_feedback>
          <limit>
            <cfm>0</cfm>
            <erp>0.2</erp>
          </limit>
          <implicit_spring_damper>1</implicit_spring_damper>
        </ode>
      </physics>
    </joint>
    <link name='left_f0_0'>
      <pose>0.0537009 1.16617 0.55221 0 -0 1.27079</pose>
      <inertial>
        <pose>0 0 0 0 -0 0</pose>
        <mass>0.0106</mass>
        <inertia>
          <ixx>1.1925e-03</ixx>
          <ixy>0</ixy>
          <ixz>0</ixz>
          <iyy>0.011505</iyy>
          <iyz>0</iyz>
          <izz>0.011505</izz>
        </inertia>
      </inertial>
      <collision name='left_f0_0_collision'>
        <pose>0 0 0.003 0 -0 0</pose>
        <geometry>
          <cylinder>
            <length>0.023</length>
            <radius>0.015</radius>
          </cylinder>
        </geometry>
        <max_contacts>1</max_contacts>
        <surface>
          <contact>
            <ode>
              <kp>1e+06</kp>
              <kd>10</kd>
              <max_vel>0.01</max_vel>
              <min_depth>0</min_depth>
            </ode>
          </contact>
          <friction>
            <ode>
              <mu>1.1</mu>
              <mu2>1.1</mu2>
            </ode>
          </friction>
        </surface>
      </collision>
      <collision name='left_f0_0_collision_left_f0_0_other'>
        <pose>0.011 0 0.003 1.5708 -0 0</pose>
        <geometry>
          <cylinder>
            <length>0.023</length>
            <radius>0.01</radius>
          </cylinder>
        </geometry>
        <max_contacts>1</max_contacts>
        <surface>
          <contact>
            <ode>
              <kp>1e+06</kp>
              <kd>10</kd>
              <max_vel>0.01</max_vel>
              <min_depth>0</min_depth>
            </ode>
          </contact>
          <friction>
            <ode>
              <mu>1.1</mu>
              <mu2>1.1</mu2>
            </ode>
          </friction>
        </surface>
      </collision>
      <visual name='left_f0_0_visual'>
        <pose>0 0 0.003 0 -0 0</pose>
        <geometry>
          <cylinder>
            <length>0.023</length>
            <radius>0.015</radius>
          </cylinder>
        </geometry>
        <material>
          <script>
            <name>Gazebo/FlatBlack</name>
            <uri>__default__</uri>
          </script>
        </material>
      </visual>
      <visual name='left_f0_0_visual_left_f0_0_1'>
        <pose>0.011 0 0.003 1.5708 -0 0</pose>
        <geometry>
          <cylinder>
            <length>0.023</length>
            <radius>0.01</radius>
          </cylinder>
        </geometry>
        <material>
          <script>
            <name>Gazebo/FlatBlack</name>
            <uri>__default__</uri>
          </script>
        </material>
      </visual>
      <gravity>1</gravity>
      <velocity_decay>
        <linear>0</linear>
        <angular>0</angular>
      </velocity_decay>
      <self_collide>0</self_collide>
    </link>
    <joint name='left_f0_j0' type='revolute'>
      <child>left_f0_0</child>
      <parent>l_hand</parent>
      <axis>
        <xyz>0 0 -1</xyz>
        <limit>
          <lower>0</lower>
          <upper>0</upper>
          <effort>11</effort>
          <velocity>-1</velocity>
        </limit>
        <dynamics>
          <damping>1</damping>
        </dynamics>
      </axis>
      <physics>
        <ode>
          <implicit_spring_damper>1</implicit_spring_damper>
          <limit>
            <cfm>0</cfm>
            <erp>0.2</erp>
          </limit>
        </ode>
      </physics>
    </joint>
    <link name='left_f0_1'>
      <pose>0.0619756 1.19292 0.55221 1.5708 2.22045e-16 1.27079</pose>
      <inertial>
        <pose>0.00697674 0 0 0 -0 0</pose>
        <mass>0.043</mass>
        <inertia>
          <ixx>2.65e-04</ixx>
          <ixy>0</ixy>
          <ixz>0</ixz>
          <iyy>2.10767e-03</iyy>
          <iyz>0</iyz>
          <izz>2.10767e-03</izz>
        </inertia>
      </inertial>
      <collision name='left_f0_1_collision'>
        <pose>0.024 0 0 3.14159 1.57079 3.14159</pose>
        <geometry>
          <cylinder>
            <length>0.067</length>
            <radius>0.01</radius>
          </cylinder>
        </geometry>
        <max_contacts>1</max_contacts>
        <surface>
          <contact>
            <ode>
              <kp>1e+06</kp>
              <kd>10</kd>
              <max_vel>0.01</max_vel>
              <min_depth>0</min_depth>
            </ode>
          </contact>
          <friction>
            <ode>
              <mu>1.1</mu>
              <mu2>1.1</mu2>
            </ode>
          </friction>
        </surface>
      </collision>
      <visual name='left_f0_1_visual'>
        <pose>0.024 0 0 3.14159 1.57079 3.14159</pose>
        <geometry>
          <cylinder>
            <length>0.067</length>
            <radius>0.01</radius>
          </cylinder>
        </geometry>
        <material>
          <script>
            <name>Gazebo/FlatBlack</name>
            <uri>__default__</uri>
          </script>
        </material>
      </visual>
      <gravity>1</gravity>
      <velocity_decay>
        <linear>0</linear>
        <angular>0</angular>
      </velocity_decay>
      <self_collide>0</self_collide>
    </link>
    <joint name='left_f0_j1' type='revolute'>
      <child>left_f0_1</child>
      <parent>left_f0_0</parent>
      <axis>
        <xyz>0.955335 -0.295526 4.89672e-12</xyz>
        <limit>
          <lower>-1.5708</lower>
          <upper>1.5708</upper>
          <effort>28</effort>
          <velocity>-1</velocity>
        </limit>
        <dynamics>
          <damping>1</damping>
        </dynamics>
      </axis>
      <physics>
        <ode>
          <implicit_spring_damper>1</implicit_spring_damper>
          <limit>
            <cfm>0</cfm>
            <erp>0.2</erp>
          </limit>
        </ode>
      </physics>
    </joint>
    <link name='left_f0_2'>
      <pose>0.0767519 1.24069 0.55221 1.5708 2.22045e-16 1.27079</pose>
      <inertial>
        <pose>0.00930233 0 0 0 -0 0</pose>
        <mass>0.043</mass>
        <inertia>
          <ixx>2.3365e-04</ixx>
          <ixy>0</ixy>
          <ixz>0</ixz>
          <iyy>2.28821e-03</iyy>
          <iyz>0</iyz>
          <izz>2.28821e-03</izz>
        </inertia>
      </inertial>
      <collision name='left_f0_2_collision'>
        <pose>0.024 0 0 3.14159 1.57079 3.14159</pose>
        <geometry>
          <cylinder>
            <length>0.057</length>
            <radius>0.009</radius>
          </cylinder>
        </geometry>
        <max_contacts>1</max_contacts>
        <surface>
          <contact>
            <ode>
              <kp>1e+06</kp>
              <kd>10</kd>
              <max_vel>0.01</max_vel>
              <min_depth>0</min_depth>
            </ode>
          </contact>
          <friction>
            <ode>
              <mu>1.1</mu>
              <mu2>1.1</mu2>
            </ode>
          </friction>
        </surface>
      </collision>
      <collision name='left_f0_2_collision_left_f0_2_other'>
        <pose>0.052 0 0 0 -0 0</pose>
        <geometry>
          <sphere>
            <radius>0.009</radius>
          </sphere>
        </geometry>
        <max_contacts>1</max_contacts>
        <surface>
          <contact>
            <ode>
              <kp>1e+06</kp>
              <kd>10</kd>
              <max_vel>0.01</max_vel>
              <min_depth>0</min_depth>
            </ode>
          </contact>
          <friction>
            <ode>
              <mu>1.1</mu>
              <mu2>1.1</mu2>
            </ode>
          </friction>
        </surface>
      </collision>
      <visual name='left_f0_2_visual'>
        <pose>0.024 0 0 3.14159 1.57079 3.14159</pose>
        <geometry>
          <cylinder>
            <length>0.057</length>
            <radius>0.009</radius>
          </cylinder>
        </geometry>
        <material>
          <script>
            <name>Gazebo/FlatBlack</name>
            <uri>__default__</uri>
          </script>
        </material>
      </visual>
      <visual name='left_f0_2_visual_left_f0_2_1'>
        <pose>0.052 0 0 0 -0 0</pose>
        <geometry>
          <sphere>
            <radius>0.009</radius>
          </sphere>
        </geometry>
        <material>
          <script>
            <name>Gazebo/FlatBlack</name>
            <uri>__default__</uri>
          </script>
        </material>
      </visual>
      <gravity>1</gravity>
      <velocity_decay>
        <linear>0</linear>
        <angular>0</angular>
      </velocity_decay>
      <self_collide>0</self_collide>
    </link>
    <joint name='left_f0_j2' type='revolute'>
      <child>left_f0_2</child>
      <parent>left_f0_1</parent>
      <axis>
        <xyz>0.955335 -0.295526 4.89672e-12</xyz>
        <limit>
          <lower>-1.5708</lower>
          <upper>1.5708</upper>
          <effort>28</effort>
          <velocity>-1</velocity>
        </limit>
        <dynamics>
          <damping>1</damping>
        </dynamics>
      </axis>
      <physics>
        <ode>
          <implicit_spring_damper>1</implicit_spring_damper>
          <limit>
            <cfm>0</cfm>
            <erp>0.2</erp>
          </limit>
        </ode>
      </physics>
    </joint>
    <link name='left_f1_0'>
      <pose>0.0849207 1.14117 0.55221 0 -0 1.27079</pose>
      <inertial>
        <pose>0 0 0 0 -0 0</pose>
        <mass>0.106</mass>
        <inertia>
          <ixx>1.1925e-03</ixx>
          <ixy>0</ixy>
          <ixz>0</ixz>
          <iyy>0.011505</iyy>
          <iyz>0</iyz>
          <izz>0.011505</izz>
        </inertia>
      </inertial>
      <collision name='left_f1_0_collision'>
        <pose>0 0 0.003 0 -0 0</pose>
        <geometry>
          <cylinder>
            <length>0.023</length>
            <radius>0.015</radius>
          </cylinder>
        </geometry>
        <max_contacts>1</max_contacts>
        <surface>
          <contact>
            <ode>
              <kp>1e+06</kp>
              <kd>10</kd>
              <max_vel>0.01</max_vel>
              <min_depth>0</min_depth>
            </ode>
          </contact>
          <friction>
            <ode>
              <mu>1.1</mu>
              <mu2>1.1</mu2>
            </ode>
          </friction>
        </surface>
      </collision>
      <collision name='left_f1_0_collision_left_f1_0_other'>
        <pose>0.011 0 0.003 1.5708 -0 0</pose>
        <geometry>
          <cylinder>
            <length>0.023</length>
            <radius>0.01</radius>
          </cylinder>
        </geometry>
        <max_contacts>1</max_contacts>
        <surface>
          <contact>
            <ode>
              <kp>1e+06</kp>
              <kd>10</kd>
              <max_vel>0.01</max_vel>
              <min_depth>0</min_depth>
            </ode>
          </contact>
          <friction>
            <ode>
              <mu>1.1</mu>
              <mu2>1.1</mu2>
            </ode>
          </friction>
        </surface>
      </collision>
      <visual name='left_f1_0_visual'>
        <pose>0 0 0.003 0 -0 0</pose>
        <geometry>
          <cylinder>
            <length>0.023</length>
            <radius>0.015</radius>
          </cylinder>
        </geometry>
        <material>
          <script>
            <name>Gazebo/FlatBlack</name>
            <uri>__default__</uri>
          </script>
        </material>
      </visual>
      <visual name='left_f1_0_visual_left_f1_0_1'>
        <pose>0.011 0 0.003 1.5708 -0 0</pose>
        <geometry>
          <cylinder>
            <length>0.023</length>
            <radius>0.01</radius>
          </cylinder>
        </geometry>
        <material>
          <script>
            <name>Gazebo/FlatBlack</name>
            <uri>__default__</uri>
          </script>
        </material>
      </visual>
      <gravity>1</gravity>
      <velocity_decay>
        <linear>0</linear>
        <angular>0</angular>
      </velocity_decay>
      <self_collide>0</self_collide>
    </link>
    <joint name='left_f1_j0' type='revolute'>
      <child>left_f1_0</child>
      <parent>l_hand</parent>
      <axis>
        <xyz>0 0 -1</xyz>
        <limit>
          <lower>0</lower>
          <upper>0</upper>
          <effort>11</effort>
          <velocity>-1</velocity>
        </limit>
        <dynamics>
          <damping>1</damping>
        </dynamics>
      </axis>
      <physics>
        <ode>
          <implicit_spring_damper>1</implicit_spring_damper>
          <limit>
            <cfm>0</cfm>
            <erp>0.2</erp>
          </limit>
        </ode>
      </physics>
    </joint>
    <link name='left_f1_1'>
      <pose>0.0931955 1.16792 0.55221 1.5708 2.22045e-16 1.27079</pose>
      <inertial>
        <pose>0.00697674 0 0 0 -0 0</pose>
        <mass>0.043</mass>
        <inertia>
          <ixx>2.65e-04</ixx>
          <ixy>0</ixy>
          <ixz>0</ixz>
          <iyy>2.10767e-03</iyy>
          <iyz>0</iyz>
          <izz>2.10767e-03</izz>
        </inertia>
      </inertial>
      <collision name='left_f1_1_collision'>
        <pose>0.024 0 0 3.14159 1.57079 3.14159</pose>
        <geometry>
          <cylinder>
            <length>0.067</length>
            <radius>0.01</radius>
          </cylinder>
        </geometry>
        <max_contacts>1</max_contacts>
        <surface>
          <contact>
            <ode>
              <kp>1e+06</kp>
              <kd>10</kd>
              <max_vel>0.01</max_vel>
              <min_depth>0</min_depth>
            </ode>
          </contact>
          <friction>
            <ode>
              <mu>1.1</mu>
              <mu2>1.1</mu2>
            </ode>
          </friction>
        </surface>
      </collision>
      <visual name='left_f1_1_visual'>
        <pose>0.024 0 0 3.14159 1.57079 3.14159</pose>
        <geometry>
          <cylinder>
            <length>0.067</length>
            <radius>0.01</radius>
          </cylinder>
        </geometry>
        <material>
          <script>
            <name>Gazebo/FlatBlack</name>
            <uri>__default__</uri>
          </script>
        </material>
      </visual>
      <gravity>1</gravity>
      <velocity_decay>
        <linear>0</linear>
        <angular>0</angular>
      </velocity_decay>
      <self_collide>0</self_collide>
    </link>
    <joint name='left_f1_j1' type='revolute'>
      <child>left_f1_1</child>
      <parent>left_f1_0</parent>
      <axis>
        <xyz>0.955335 -0.295526 4.89672e-12</xyz>
        <limit>
          <lower>-1.5708</lower>
          <upper>1.5708</upper>
          <effort>28</effort>
          <velocity>-1</velocity>
        </limit>
        <dynamics>
          <damping>1</damping>
        </dynamics>
      </axis>
      <physics>
        <ode>
          <implicit_spring_damper>1</implicit_spring_damper>
          <limit>
            <cfm>0</cfm>
            <erp>0.2</erp>
          </limit>
        </ode>
      </physics>
    </joint>
    <link name='left_f1_2'>
      <pose>0.107972 1.21569 0.55221 1.5708 2.22045e-16 1.27079</pose>
      <inertial>
        <pose>0.00930233 0 0 0 -0 0</pose>
        <mass>0.043</mass>
        <inertia>
          <ixx>2.3365e-04</ixx>
          <ixy>0</ixy>
          <ixz>0</ixz>
          <iyy>2.28821e-03</iyy>
          <iyz>0</iyz>
          <izz>2.28821e-03</izz>
        </inertia>
      </inertial>
      <collision name='left_f1_2_collision'>
        <pose>0.024 0 0 3.14159 1.57079 3.14159</pose>
        <geometry>
          <cylinder>
            <length>0.057</length>
            <radius>0.009</radius>
          </cylinder>
        </geometry>
        <max_contacts>1</max_contacts>
        <surface>
          <contact>
            <ode>
              <kp>1e+06</kp>
              <kd>10</kd>
              <max_vel>0.01</max_vel>
              <min_depth>0</min_depth>
            </ode>
          </contact>
          <friction>
            <ode>
              <mu>1.1</mu>
              <mu2>1.1</mu2>
            </ode>
          </friction>
        </surface>
      </collision>
      <collision name='left_f1_2_collision_left_f1_2_other'>
        <pose>0.052 0 0 0 -0 0</pose>
        <geometry>
          <sphere>
            <radius>0.009</radius>
          </sphere>
        </geometry>
        <max_contacts>1</max_contacts>
        <surface>
          <contact>
            <ode>
              <kp>1e+06</kp>
              <kd>10</kd>
              <max_vel>0.01</max_vel>
              <min_depth>0</min_depth>
            </ode>
          </contact>
          <friction>
            <ode>
              <mu>1.1</mu>
              <mu2>1.1</mu2>
            </ode>
          </friction>
        </surface>
      </collision>
      <visual name='left_f1_2_visual'>
        <pose>0.024 0 0 3.14159 1.57079 3.14159</pose>
        <geometry>
          <cylinder>
            <length>0.057</length>
            <radius>0.009</radius>
          </cylinder>
        </geometry>
        <material>
          <script>
            <name>Gazebo/FlatBlack</name>
            <uri>__default__</uri>
          </script>
        </material>
      </visual>
      <visual name='left_f1_2_visual_left_f1_2_1'>
        <pose>0.052 0 0 0 -0 0</pose>
        <geometry>
          <sphere>
            <radius>0.009</radius>
          </sphere>
        </geometry>
        <material>
          <script>
            <name>Gazebo/FlatBlack</name>
            <uri>__default__</uri>
          </script>
        </material>
      </visual>
      <gravity>1</gravity>
      <velocity_decay>
        <linear>0</linear>
        <angular>0</angular>
      </velocity_decay>
      <self_collide>0</self_collide>
    </link>
    <joint name='left_f1_j2' type='revolute'>
      <child>left_f1_2</child>
      <parent>left_f1_1</parent>
      <axis>
        <xyz>0.955335 -0.295526 4.89672e-12</xyz>
        <limit>
          <lower>-1.5708</lower>
          <upper>1.5708</upper>
          <effort>28</effort>
          <velocity>-1</velocity>
        </limit>
        <dynamics>
          <damping>1</damping>
        </dynamics>
      </axis>
      <physics>
        <ode>
          <implicit_spring_damper>1</implicit_spring_damper>
          <limit>
            <cfm>0</cfm>
            <erp>0.2</erp>
          </limit>
        </ode>
      </physics>
    </joint>
    <link name='left_f2_0'>
      <pose>0.116151 1.11617 0.55221 0 -0 1.27079</pose>
      <inertial>
        <pose>0 0 0 0 -0 0</pose>
        <mass>0.106</mass>
        <inertia>
          <ixx>1.1925e-03</ixx>
          <ixy>0</ixy>
          <ixz>0</ixz>
          <iyy>0.011505</iyy>
          <iyz>0</iyz>
          <izz>0.011505</izz>
        </inertia>
      </inertial>
      <collision name='left_f2_0_collision'>
        <pose>0 0 0.003 0 -0 0</pose>
        <geometry>
          <cylinder>
            <length>0.023</length>
            <radius>0.015</radius>
          </cylinder>
        </geometry>
        <max_contacts>1</max_contacts>
        <surface>
          <contact>
            <ode>
              <kp>1e+06</kp>
              <kd>10</kd>
              <max_vel>0.01</max_vel>
              <min_depth>0</min_depth>
            </ode>
          </contact>
          <friction>
            <ode>
              <mu>1.1</mu>
              <mu2>1.1</mu2>
            </ode>
          </friction>
        </surface>
      </collision>
      <collision name='left_f2_0_collision_left_f2_0_other'>
        <pose>0.011 0 0.003 1.5708 -0 0</pose>
        <geometry>
          <cylinder>
            <length>0.023</length>
            <radius>0.01</radius>
          </cylinder>
        </geometry>
        <max_contacts>1</max_contacts>
        <surface>
          <contact>
            <ode>
              <kp>1e+06</kp>
              <kd>10</kd>
              <max_vel>0.01</max_vel>
              <min_depth>0</min_depth>
            </ode>
          </contact>
          <friction>
            <ode>
              <mu>1.1</mu>
              <mu2>1.1</mu2>
            </ode>
          </friction>
        </surface>
      </collision>
      <visual name='left_f2_0_visual'>
        <pose>0 0 0.003 0 -0 0</pose>
        <geometry>
          <cylinder>
            <length>0.023</length>
            <radius>0.015</radius>
          </cylinder>
        </geometry>
        <material>
          <script>
            <name>Gazebo/FlatBlack</name>
            <uri>__default__</uri>
          </script>
        </material>
      </visual>
      <visual name='left_f2_0_visual_left_f2_0_1'>
        <pose>0.011 0 0.003 1.5708 -0 0</pose>
        <geometry>
          <cylinder>
            <length>0.023</length>
            <radius>0.01</radius>
          </cylinder>
        </geometry>
        <material>
          <script>
            <name>Gazebo/FlatBlack</name>
            <uri>__default__</uri>
          </script>
        </material>
      </visual>
      <gravity>1</gravity>
      <velocity_decay>
        <linear>0</linear>
        <angular>0</angular>
      </velocity_decay>
      <self_collide>0</self_collide>
    </link>
    <joint name='left_f2_j0' type='revolute'>
      <child>left_f2_0</child>
      <parent>l_hand</parent>
      <axis>
        <xyz>0 0 -1</xyz>
        <limit>
          <lower>0</lower>
          <upper>0</upper>
          <effort>11</effort>
          <velocity>-1</velocity>
        </limit>
        <dynamics>
          <damping>1</damping>
        </dynamics>
      </axis>
      <physics>
        <ode>
          <implicit_spring_damper>1</implicit_spring_damper>
          <limit>
            <cfm>0</cfm>
            <erp>0.2</erp>
          </limit>
        </ode>
      </physics>
    </joint>
    <link name='left_f2_1'>
      <pose>0.124425 1.14292 0.55221 1.5708 2.22045e-16 1.27079</pose>
      <inertial>
        <pose>0.00697674 0 0 0 -0 0</pose>
        <mass>0.043</mass>
        <inertia>
          <ixx>2.65e-04</ixx>
          <ixy>0</ixy>
          <ixz>0</ixz>
          <iyy>2.10767e-03</iyy>
          <iyz>0</iyz>
          <izz>2.10767e-03</izz>
        </inertia>
      </inertial>
      <collision name='left_f2_1_collision'>
        <pose>0.024 0 0 3.14159 1.57079 3.14159</pose>
        <geometry>
          <cylinder>
            <length>0.067</length>
            <radius>0.01</radius>
          </cylinder>
        </geometry>
        <max_contacts>1</max_contacts>
        <surface>
          <contact>
            <ode>
              <kp>1e+06</kp>
              <kd>10</kd>
              <max_vel>0.01</max_vel>
              <min_depth>0</min_depth>
            </ode>
          </contact>
          <friction>
            <ode>
              <mu>1.1</mu>
              <mu2>1.1</mu2>
            </ode>
          </friction>
        </surface>
      </collision>
      <visual name='left_f2_1_visual'>
        <pose>0.024 0 0 3.14159 1.57079 3.14159</pose>
        <geometry>
          <cylinder>
            <length>0.067</length>
            <radius>0.01</radius>
          </cylinder>
        </geometry>
        <material>
          <script>
            <name>Gazebo/FlatBlack</name>
            <uri>__default__</uri>
          </script>
        </material>
      </visual>
      <gravity>1</gravity>
      <velocity_decay>
        <linear>0</linear>
        <angular>0</angular>
      </velocity_decay>
      <self_collide>0</self_collide>
    </link>
    <joint name='left_f2_j1' type='revolute'>
      <child>left_f2_1</child>
      <parent>left_f2_0</parent>
      <axis>
        <xyz>0.955335 -0.295526 4.89672e-12</xyz>
        <limit>
          <lower>-1.5708</lower>
          <upper>1.5708</upper>
          <effort>28</effort>
          <velocity>-1</velocity>
        </limit>
        <dynamics>
          <damping>1</damping>
        </dynamics>
      </axis>
      <physics>
        <ode>
          <implicit_spring_damper>1</implicit_spring_damper>
          <limit>
            <cfm>0</cfm>
            <erp>0.2</erp>
          </limit>
        </ode>
      </physics>
    </joint>
    <link name='left_f2_2'>
      <pose>0.139202 1.19069 0.55221 1.5708 2.22045e-16 1.27079</pose>
      <inertial>
        <pose>0.00930233 0 0 0 -0 0</pose>
        <mass>0.043</mass>
        <inertia>
          <ixx>2.3365e-04</ixx>
          <ixy>0</ixy>
          <ixz>0</ixz>
          <iyy>2.28821e-03</iyy>
          <iyz>0</iyz>
          <izz>2.28821e-03</izz>
        </inertia>
      </inertial>
      <collision name='left_f2_2_collision'>
        <pose>0.024 0 0 3.14159 1.57079 3.14159</pose>
        <geometry>
          <cylinder>
            <length>0.057</length>
            <radius>0.009</radius>
          </cylinder>
        </geometry>
        <max_contacts>1</max_contacts>
        <surface>
          <contact>
            <ode>
              <kp>1e+06</kp>
              <kd>10</kd>
              <max_vel>0.01</max_vel>
              <min_depth>0</min_depth>
            </ode>
          </contact>
          <friction>
            <ode>
              <mu>1.1</mu>
              <mu2>1.1</mu2>
            </ode>
          </friction>
        </surface>
      </collision>
      <collision name='left_f2_2_collision_left_f2_2_other'>
        <pose>0.052 0 0 0 -0 0</pose>
        <geometry>
          <sphere>
            <radius>0.009</radius>
          </sphere>
        </geometry>
        <max_contacts>1</max_contacts>
        <surface>
          <contact>
            <ode>
              <kp>1e+06</kp>
              <kd>10</kd>
              <max_vel>0.01</max_vel>
              <min_depth>0</min_depth>
            </ode>
          </contact>
          <friction>
            <ode>
              <mu>1.1</mu>
              <mu2>1.1</mu2>
            </ode>
          </friction>
        </surface>
      </collision>
      <visual name='left_f2_2_visual'>
        <pose>0.024 0 0 3.14159 1.57079 3.14159</pose>
        <geometry>
          <cylinder>
            <length>0.057</length>
            <radius>0.009</radius>
          </cylinder>
        </geometry>
        <material>
          <script>
            <name>Gazebo/FlatBlack</name>
            <uri>__default__</uri>
          </script>
        </material>
      </visual>
      <visual name='left_f2_2_visual_left_f2_2_1'>
        <pose>0.052 0 0 0 -0 0</pose>
        <geometry>
          <sphere>
            <radius>0.009</radius>
          </sphere>
        </geometry>
        <material>
          <script>
            <name>Gazebo/FlatBlack</name>
            <uri>__default__</uri>
          </script>
        </material>
      </visual>
      <gravity>1</gravity>
      <velocity_decay>
        <linear>0</linear>
        <angular>0</angular>
      </velocity_decay>
      <self_collide>0</self_collide>
    </link>
    <joint name='left_f2_j2' type='revolute'>
      <child>left_f2_2</child>
      <parent>left_f2_1</parent>
      <axis>
        <xyz>0.955335 -0.295526 4.89672e-12</xyz>
        <limit>
          <lower>-1.5708</lower>
          <upper>1.5708</upper>
          <effort>28</effort>
          <velocity>-1</velocity>
        </limit>
        <dynamics>
          <damping>1</damping>
        </dynamics>
      </axis>
      <physics>
        <ode>
          <implicit_spring_damper>1</implicit_spring_damper>
          <limit>
            <cfm>0</cfm>
            <erp>0.2</erp>
          </limit>
        </ode>
      </physics>
    </joint>
    <link name='left_f3_0'>
      <pose>0.00987025 1.06612 0.56621 3.14158 -1.57079 0.785413</pose>
      <inertial>
        <pose>0 0 0 0 -0 0</pose>
        <mass>0.106</mass>
        <inertia>
          <ixx>1.1925e-03</ixx>
          <ixy>0</ixy>
          <ixz>0</ixz>
          <iyy>0.011505</iyy>
          <iyz>0</iyz>
          <izz>0.011505</izz>
        </inertia>
      </inertial>
      <collision name='left_f3_0_collision'>
        <pose>0 0 0.003 0 -0 0</pose>
        <geometry>
          <cylinder>
            <length>0.023</length>
            <radius>0.015</radius>
          </cylinder>
        </geometry>
        <max_contacts>1</max_contacts>
        <surface>
          <contact>
            <ode>
              <kp>1e+06</kp>
              <kd>10</kd>
              <max_vel>0.01</max_vel>
              <min_depth>0</min_depth>
            </ode>
          </contact>
          <friction>
            <ode>
              <mu>1.1</mu>
              <mu2>1.1</mu2>
            </ode>
          </friction>
        </surface>
      </collision>
      <collision name='left_f3_0_collision_left_f3_0_other'>
        <pose>0.011 0 0.003 1.5708 -0 0</pose>
        <geometry>
          <cylinder>
            <length>0.023</length>
            <radius>0.01</radius>
          </cylinder>
        </geometry>
        <max_contacts>1</max_contacts>
        <surface>
          <contact>
            <ode>
              <kp>1e+06</kp>
              <kd>10</kd>
              <max_vel>0.01</max_vel>
              <min_depth>0</min_depth>
            </ode>
          </contact>
          <friction>
            <ode>
              <mu>1.1</mu>
              <mu2>1.1</mu2>
            </ode>
          </friction>
        </surface>
      </collision>
      <visual name='left_f3_0_visual'>
        <pose>0 0 0.003 0 -0 0</pose>
        <geometry>
          <cylinder>
            <length>0.023</length>
            <radius>0.015</radius>
          </cylinder>
        </geometry>
        <material>
          <script>
            <name>Gazebo/FlatBlack</name>
            <uri>__default__</uri>
          </script>
        </material>
      </visual>
      <visual name='left_f3_0_visual_left_f3_0_1'>
        <pose>0.011 0 0.003 1.5708 -0 0</pose>
        <geometry>
          <cylinder>
            <length>0.023</length>
            <radius>0.01</radius>
          </cylinder>
        </geometry>
        <material>
          <script>
            <name>Gazebo/FlatBlack</name>
            <uri>__default__</uri>
          </script>
        </material>
      </visual>
      <gravity>1</gravity>
      <velocity_decay>
        <linear>0</linear>
        <angular>0</angular>
      </velocity_decay>
      <self_collide>0</self_collide>
    </link>
    <joint name='left_f3_j0' type='revolute'>
      <child>left_f3_0</child>
      <parent>l_hand</parent>
      <axis>
        <xyz>-0.707107 -0.707106 -4.89664e-12</xyz>
        <limit>
          <lower>0</lower>
          <upper>0</upper>
          <effort>11</effort>
          <velocity>-1</velocity>
        </limit>
        <dynamics>
          <damping>1</damping>
        </dynamics>
      </axis>
      <physics>
        <ode>
          <implicit_spring_damper>1</implicit_spring_damper>
          <limit>
            <cfm>0</cfm>
            <erp>0.2</erp>
          </limit>
        </ode>
      </physics>
    </joint>
    <link name='left_f3_1'>
      <pose>0.00987025 1.06612 0.59421 -1.5708 -1.57079 0.785403</pose>
      <inertial>
        <pose>0.00697674 0 0 0 -0 0</pose>
        <mass>0.043</mass>
        <inertia>
          <ixx>2.65e-04</ixx>
          <ixy>0</ixy>
          <ixz>0</ixz>
          <iyy>2.10767e-03</iyy>
          <iyz>0</iyz>
          <izz>2.10767e-03</izz>
        </inertia>
      </inertial>
      <collision name='left_f3_1_collision'>
        <pose>0.024 0 0 3.14159 1.57079 3.14159</pose>
        <geometry>
          <cylinder>
            <length>0.067</length>
            <radius>0.01</radius>
          </cylinder>
        </geometry>
        <max_contacts>1</max_contacts>
        <surface>
          <contact>
            <ode>
              <kp>1e+06</kp>
              <kd>10</kd>
              <max_vel>0.01</max_vel>
              <min_depth>0</min_depth>
            </ode>
          </contact>
          <friction>
            <ode>
              <mu>1.1</mu>
              <mu2>1.1</mu2>
            </ode>
          </friction>
        </surface>
      </collision>
      <visual name='left_f3_1_visual'>
        <pose>0.024 0 0 3.14159 1.57079 3.14159</pose>
        <geometry>
          <cylinder>
            <length>0.067</length>
            <radius>0.01</radius>
          </cylinder>
        </geometry>
        <material>
          <script>
            <name>Gazebo/FlatBlack</name>
            <uri>__default__</uri>
          </script>
        </material>
      </visual>
      <gravity>1</gravity>
      <velocity_decay>
        <linear>0</linear>
        <angular>0</angular>
      </velocity_decay>
      <self_collide>0</self_collide>
    </link>
    <joint name='left_f3_j1' type='revolute'>
      <child>left_f3_1</child>
      <parent>left_f3_0</parent>
      <axis>
        <xyz>-0.707106 0.707107 -2.77556e-17</xyz>
        <limit>
          <lower>-1.5708</lower>
          <upper>1.5708</upper>
          <effort>28</effort>
          <velocity>-1</velocity>
        </limit>
        <dynamics>
          <damping>1</damping>
        </dynamics>
      </axis>
      <physics>
        <ode>
          <implicit_spring_damper>1</implicit_spring_damper>
          <limit>
            <cfm>0</cfm>
            <erp>0.2</erp>
          </limit>
        </ode>
      </physics>
    </joint>
    <link name='left_f3_2'>
      <pose>0.00987025 1.06612 0.64421 -1.5708 -1.57079 0.785403</pose>
      <inertial>
        <pose>0.00930233 0 0 0 -0 0</pose>
        <mass>0.043</mass>
        <inertia>
          <ixx>2.3365e-04</ixx>
          <ixy>0</ixy>
          <ixz>0</ixz>
          <iyy>2.28821e-03</iyy>
          <iyz>0</iyz>
          <izz>2.28821e-03</izz>
        </inertia>
      </inertial>
      <collision name='left_f3_2_collision'>
        <pose>0.024 0 0 3.14159 1.57079 3.14159</pose>
        <geometry>
          <cylinder>
            <length>0.057</length>
            <radius>0.009</radius>
          </cylinder>
        </geometry>
        <max_contacts>1</max_contacts>
        <surface>
          <contact>
            <ode>
              <kp>1e+06</kp>
              <kd>10</kd>
              <max_vel>0.01</max_vel>
              <min_depth>0</min_depth>
            </ode>
          </contact>
          <friction>
            <ode>
              <mu>1.1</mu>
              <mu2>1.1</mu2>
            </ode>
          </friction>
        </surface>
      </collision>
      <collision name='left_f3_2_collision_left_f3_2_other'>
        <pose>0.052 0 0 0 -0 0</pose>
        <geometry>
          <sphere>
            <radius>0.009</radius>
          </sphere>
        </geometry>
        <max_contacts>1</max_contacts>
        <surface>
          <contact>
            <ode>
              <kp>1e+06</kp>
              <kd>10</kd>
              <max_vel>0.01</max_vel>
              <min_depth>0</min_depth>
            </ode>
          </contact>
          <friction>
            <ode>
              <mu>1.1</mu>
              <mu2>1.1</mu2>
            </ode>
          </friction>
        </surface>
      </collision>
      <visual name='left_f3_2_visual'>
        <pose>0.024 0 0 3.14159 1.57079 3.14159</pose>
        <geometry>
          <cylinder>
            <length>0.057</length>
            <radius>0.009</radius>
          </cylinder>
        </geometry>
        <material>
          <script>
            <name>Gazebo/FlatBlack</name>
            <uri>__default__</uri>
          </script>
        </material>
      </visual>
      <visual name='left_f3_2_visual_left_f3_2_1'>
        <pose>0.052 0 0 0 -0 0</pose>
        <geometry>
          <sphere>
            <radius>0.009</radius>
          </sphere>
        </geometry>
        <material>
          <script>
            <name>Gazebo/FlatBlack</name>
            <uri>__default__</uri>
          </script>
        </material>
      </visual>
      <gravity>1</gravity>
      <velocity_decay>
        <linear>0</linear>
        <angular>0</angular>
      </velocity_decay>
      <self_collide>0</self_collide>
    </link>
    <joint name='left_f3_j2' type='revolute'>
      <child>left_f3_2</child>
      <parent>left_f3_1</parent>
      <axis>
        <xyz>-0.707106 0.707107 -2.77556e-17</xyz>
        <limit>
          <lower>-1.5708</lower>
          <upper>1.5708</upper>
          <effort>28</effort>
          <velocity>-1</velocity>
        </limit>
        <dynamics>
          <damping>1</damping>
        </dynamics>
      </axis>
      <physics>
        <ode>
          <implicit_spring_damper>1</implicit_spring_damper>
          <limit>
            <cfm>0</cfm>
            <erp>0.2</erp>
          </limit>
        </ode>
      </physics>
    </joint>
    <!--
    <link name='head'>
      <pose>0.20422 0 0.74993 0 -0 0</pose>
      <inertial>
        <pose>-0.0754942 3.38765e-05 0.0277411 0 -0 0</pose>
        <mass>.141991</mass>
        <inertia>
          <ixx>0.00361284</ixx>
          <ixy>-1.51324e-06</ixy>
          <ixz>-0.000892818</ixz>
          <iyy>0.00208745</iyy>
          <iyz>-6.83342e-07</iyz>
          <izz>0.00179047</izz>
        </inertia>
      </inertial>
      <visual name='head_visual'>
      <pose>0.20422 0 0.74993 0 -0 0</pose>
        <geometry>
          <mesh>
            <scale>1 1 1</scale>
            <uri>model://multisense_sl/meshes/head.dae</uri>
          </mesh>
        </geometry>
      </visual>
      <visual name='head_visual_head_imu_link'>
        <pose>-0.0475 0.035 0 0 -0 0</pose>
        <geometry>
          <box>
            <size>0.01 0.01 0.01</size>
          </box>
        </geometry>
      </visual>
    </link>
    <joint name='neck_ry' type='revolute'>
      <child>head</child>
      <parent>utorso</parent>
      <axis>
        <xyz>0 1 0</xyz>
        <limit>
          <lower>0</lower>
          <upper>0</upper>
          <effort>5</effort>
          <velocity>12</velocity>
        </limit>
        <dynamics>
          <damping>0.1</damping>
        </dynamics>
      </axis>
      <physics>
        <ode>
          <implicit_spring_damper>1</implicit_spring_damper>
          <limit>
            <cfm>0</cfm>
            <erp>0.2</erp>
          </limit>
        </ode>
      </physics>
    </joint>
    <link name='hokuyo_link'>
      <pose>0.15962 0 0.83793 0 -0 0</pose>
      <inertial>
        <pose>0.0124384 0.0004084 -0.0041783 0 -0 0</pose>
        <mass>0.0057664</mass>
        <inertia>
          <ixx>0.000401606</ixx>
          <ixy>4.9927e-08</ixy>
          <ixz>1.0997e-05</ixz>
          <iyy>0.00208115</iyy>
          <iyz>-9.8165e-09</iyz>
          <izz>0.00178402</izz>
        </inertia>
      </inertial>
      <collision name='hokuyo_link_collision'>
        <pose>0.01885 0 -0.02119 0 -0 0</pose>
        <geometry>
          <box>
            <size>0.08 0.06 0.04238</size>
          </box>
        </geometry>
        <surface>
          <contact>
            <ode/>
          </contact>
          <friction>
            <ode>
              <mu>0.9</mu>
              <mu2>0.9</mu2>
            </ode>
          </friction>
        </surface>
      </collision>
      <collision name='hokuyo_link_collision_hokuyo_link_other'>
        <pose>0.03 0 0.0235 0 -0 0</pose>
        <geometry>
          <cylinder>
            <length>0.047</length>
            <radius>0.024425</radius>
          </cylinder>
        </geometry>
        <surface>
          <contact>
            <ode/>
          </contact>
          <friction>
            <ode>
              <mu>0.9</mu>
              <mu2>0.9</mu2>
            </ode>
          </friction>
        </surface>
      </collision>
      <visual name='hokuyo_link_visual'>
        <pose>0.045 -0.0261018 -0.0834237 -0.314 0 0</pose>
        <geometry>
          <mesh>
            <scale>1 1 1</scale>
            <uri>model://multisense_sl/meshes/head_camera.dae</uri>
          </mesh>
        </geometry>
      </visual>
      <velocity_decay>
        <linear>0</linear>
        <angular>0</angular>
      </velocity_decay>
      <gravity>1</gravity>
      <velocity_decay>
        <linear>0</linear>
        <angular>0</angular>
      </velocity_decay>
      <self_collide>0</self_collide>
    </link>
    <joint name='hokuyo_joint' type='revolute'>
      <child>hokuyo_link</child>
      <parent>head</parent>
      <axis>
        <xyz>1 0 0</xyz>
        <limit>
          <lower>0</lower>
          <upper>0</upper>
        </limit>
        <dynamics>
          <damping>0.01</damping>
        </dynamics>
      </axis>
    </joint>
-->
    <link name='r_clav'>
      <pose>0.05191 -0.13866 0.31915 0 -0 0</pose>
      <inertial>
        <pose>0 -0.048 0.084 0 -0 0</pose>
        <mass>.345</mass>
        <inertia>
          <ixx>0.011</ixx>
          <ixy>0</ixy>
          <ixz>0</ixz>
          <iyy>0.009</iyy>
          <iyz>0.004</iyz>
          <izz>0.004</izz>
        </inertia>
      </inertial>
      <!--
      <collision name='r_clav_collision'>
        <pose>0 0 0 0 -0 0</pose>
        <geometry>
          <mesh>
            <scale>1 1 1</scale>
            <uri>model://atlas_hydra/meshes/r_clav.DAE</uri>
          </mesh>
        </geometry>
        <surface>
          <contact>
            <ode/>
          </contact>
          <friction>
            <ode>
              <mu>0.9</mu>
              <mu2>0.9</mu2>
            </ode>
          </friction>
        </surface>
      </collision>
-->
      <visual name='r_clav_visual'>
        <pose>0 0 0 0 -0 0</pose>
        <geometry>
          <mesh>
            <scale>1 1 1</scale>
            <uri>model://atlas_hydra/meshes/r_clav.DAE</uri>
          </mesh>
        </geometry>
      </visual>
      <gravity>1</gravity>
      <velocity_decay>
        <linear>0</linear>
        <angular>0</angular>
      </velocity_decay>
      <self_collide>0</self_collide>
    </link>
    <joint name='r_arm_shy' type='revolute'>
      <child>r_clav</child>
      <parent>pelvis</parent>
      <axis>
        <xyz>0 0.5 -0.866025</xyz>
        <limit>
          <!--
          <lower>-1.5708</lower>
          <upper>0.785398</upper>
-->
          <effort>212</effort>
          <velocity>12</velocity>
        </limit>
        <dynamics>
          <damping>0.1</damping>
        </dynamics>
      </axis>
      <physics>
        <ode>
          <implicit_spring_damper>1</implicit_spring_damper>
          <limit>
            <cfm>0</cfm>
            <erp>0.2</erp>
          </limit>
        </ode>
      </physics>
    </joint>
    <link name='r_scap'>
      <pose>0.05191 -0.27901 0.51524 0 -0 0</pose>
      <inertial>
        <pose>0 0 0 0 -0 0</pose>
        <mass>.3012</mass>
        <inertia>
          <ixx>0.00319</ixx>
          <ixy>0</ixy>
          <ixz>0</ixz>
          <iyy>0.00583</iyy>
          <iyz>0</iyz>
          <izz>0.00583</izz>
        </inertia>
      </inertial>
      <!--
      <collision name='r_scap_collision'>
        <pose>0 0 0 0 -0 0</pose>
        <geometry>
          <mesh>
            <scale>1 1 1</scale>
            <uri>model://atlas_hydra/meshes/r_sh_rx.DAE</uri>
          </mesh>
        </geometry>
        <surface>
          <contact>
            <ode/>
          </contact>
          <friction>
            <ode>
              <mu>0.9</mu>
              <mu2>0.9</mu2>
            </ode>
          </friction>
        </surface>
      </collision>
-->
      <visual name='r_scap_visual'>
        <pose>0 0 0 0 -0 0</pose>
        <geometry>
          <mesh>
            <scale>1 1 1</scale>
            <uri>model://atlas_hydra/meshes/r_sh_rx.DAE</uri>
          </mesh>
        </geometry>
      </visual>
      <gravity>1</gravity>
      <velocity_decay>
        <linear>0</linear>
        <angular>0</angular>
      </velocity_decay>
      <self_collide>0</self_collide>
    </link>
    <joint name='r_arm_shx' type='revolute'>
      <child>r_scap</child>
      <parent>r_clav</parent>
      <axis>
        <xyz>1 0 0</xyz>
        <limit>
          <!--
          <lower>-1.5708</lower>
          <upper>1.5708</upper>
-->
          <effort>170</effort>
          <velocity>12</velocity>
        </limit>
        <dynamics>
          <damping>0.1</damping>
        </dynamics>
      </axis>
      <physics>
        <ode>
          <implicit_spring_damper>1</implicit_spring_damper>
          <limit>
            <cfm>0</cfm>
            <erp>0.2</erp>
          </limit>
        </ode>
      </physics>
    </joint>
    <link name='r_uarm'>
      <pose>0.05191 -0.46601 0.53124 0 -0 0</pose>
      <inertial>
        <pose>0 0.065 0 0 -0 0</pose>
        <mass>.3388</mass>
        <inertia>
          <ixx>0.00656</ixx>
          <ixy>0</ixy>
          <ixz>0</ixz>
          <iyy>0.00358</iyy>
          <iyz>0</iyz>
          <izz>0.00656</izz>
        </inertia>
      </inertial>
      <!--
      <collision name='r_uarm_collision'>
        <pose>0 0 0 0 -0 0</pose>
        <geometry>
          <mesh>
            <scale>1 1 1</scale>
            <uri>model://atlas_hydra/meshes/r_elbow_ry.DAE</uri>
          </mesh>
        </geometry>
        <surface>
          <contact>
            <ode/>
          </contact>
          <friction>
            <ode>
              <mu>0.9</mu>
              <mu2>0.9</mu2>
            </ode>
          </friction>
        </surface>
      </collision>
-->
      <visual name='r_uarm_visual'>
        <pose>0 0 0 0 -0 0</pose>
        <geometry>
          <mesh>
            <scale>1 1 1</scale>
            <uri>model://atlas_hydra/meshes/r_elbow_ry.DAE</uri>
          </mesh>
        </geometry>
      </visual>
      <gravity>1</gravity>
      <velocity_decay>
        <linear>0</linear>
        <angular>0</angular>
      </velocity_decay>
      <self_collide>0</self_collide>
    </link>
    <joint name='r_arm_ely' type='revolute'>
      <child>r_uarm</child>
      <parent>r_scap</parent>
      <axis>
        <xyz>0 1 0</xyz>
        <limit>
          <!--
          <lower>0</lower>
          <upper>3.14159</upper>
-->
          <effort>114</effort>
          <velocity>12</velocity>
        </limit>
        <dynamics>
          <damping>0.1</damping>
        </dynamics>
      </axis>
      <physics>
        <ode>
          <implicit_spring_damper>1</implicit_spring_damper>
          <limit>
            <cfm>0</cfm>
            <erp>0.2</erp>
          </limit>
        </ode>
      </physics>
    </joint>
    <link name='r_larm'>
      <pose>0.05191 -0.58501 0.54045 0 -0 0</pose>
      <inertial>
        <pose>0 0 0 0 -0 0</pose>
        <mass>.2509</mass>
        <inertia>
          <ixx>0.00265</ixx>
          <ixy>0</ixy>
          <ixz>0</ixz>
          <iyy>0.00446</iyy>
          <iyz>0</iyz>
          <izz>0.00446</izz>
        </inertia>
      </inertial>
      <!--
      <collision name='r_larm_collision'>
        <pose>0 0 0 0 -0 0</pose>
        <geometry>
          <mesh>
            <scale>1 1 1</scale>
            <uri>model://atlas_hydra/meshes/r_elbow_rx.DAE</uri>
          </mesh>
        </geometry>
        <surface>
          <contact>
            <ode/>
          </contact>
          <friction>
            <ode>
              <mu>0.9</mu>
              <mu2>0.9</mu2>
            </ode>
          </friction>
        </surface>
      </collision>
-->
      <visual name='r_larm_visual'>
        <pose>0 0 0 0 -0 0</pose>
        <geometry>
          <mesh>
            <scale>1 1 1</scale>
            <uri>model://atlas_hydra/meshes/r_elbow_rx.DAE</uri>
          </mesh>
        </geometry>
      </visual>
      <gravity>1</gravity>
      <velocity_decay>
        <linear>0</linear>
        <angular>0</angular>
      </velocity_decay>
      <self_collide>0</self_collide>
    </link>
    <joint name='r_arm_elx' type='revolute'>
      <child>r_larm</child>
      <parent>r_uarm</parent>
      <axis>
        <xyz>1 0 0</xyz>
        <limit>
          <!--
          <lower>-2.35619</lower>
          <upper>0</upper>
-->
          <effort>114</effort>
          <velocity>12</velocity>
        </limit>
        <dynamics>
          <damping>0.1</damping>
        </dynamics>
      </axis>
      <physics>
        <ode>
          <implicit_spring_damper>1</implicit_spring_damper>
          <limit>
            <cfm>0</cfm>
            <erp>0.2</erp>
          </limit>
        </ode>
      </physics>
    </joint>
    <link name='r_farm'>
      <pose>0.05191 -0.77201 0.53124 0 -0 0</pose>
      <inertial>
        <pose>0 0.065 0 0 -0 0</pose>
        <mass>.3388</mass>
        <inertia>
          <ixx>0.00656</ixx>
          <ixy>0</ixy>
          <ixz>0</ixz>
          <iyy>0.00358</iyy>
          <iyz>0</iyz>
          <izz>0.00656</izz>
        </inertia>
      </inertial>
      <!--
      <collision name='r_farm_collision'>
        <pose>0 0 0 0 -0 0</pose>
        <geometry>
          <mesh>
            <scale>1 1 1</scale>
            <uri>model://atlas_hydra/meshes/r_farm.DAE</uri>
          </mesh>
        </geometry>
        <surface>
          <contact>
            <ode/>
          </contact>
          <friction>
            <ode>
              <mu>0.9</mu>
              <mu2>0.9</mu2>
            </ode>
          </friction>
        </surface>
      </collision>
-->
      <visual name='r_farm_visual'>
        <pose>0 0 0 0 -0 0</pose>
        <geometry>
          <mesh>
            <scale>1 1 1</scale>
            <uri>model://atlas_hydra/meshes/r_farm.DAE</uri>
          </mesh>
        </geometry>
      </visual>
      <gravity>1</gravity>
      <velocity_decay>
        <linear>0</linear>
        <angular>0</angular>
      </velocity_decay>
      <self_collide>0</self_collide>
    </link>
    <joint name='r_arm_wry' type='revolute'>
      <child>r_farm</child>
      <parent>r_larm</parent>
      <axis>
        <xyz>0 1 0</xyz>
        <limit>
          <!--
          <lower>0</lower>
          <upper>3.14159</upper>
-->
          <effort>114</effort>
          <velocity>12</velocity>
        </limit>
        <dynamics>
          <damping>0.1</damping>
        </dynamics>
      </axis>
      <physics>
        <ode>
          <implicit_spring_damper>1</implicit_spring_damper>
          <limit>
            <cfm>0</cfm>
            <erp>0.2</erp>
          </limit>
        </ode>
      </physics>
    </joint>
    <link name='r_hand'>
      <pose>0.05191 -0.89101 0.54045 0 -0 0</pose>
      <inertial>
        <pose>0.00182184 -0.0860336 0.00645092 0 -0 0</pose>
        <mass>.4872</mass>
        <inertia>
          <ixx>0.049418</ixx>
          <ixy>0.00215162</ixy>
          <ixz>8.22671e-05</ixz>
          <iyy>0.00800371</iyy>
          <iyz>0.00287073</iyz>
          <izz>0.0526565</izz>
        </inertia>
      </inertial>
      <collision name='r_hand_collision'>
        <pose>0 0 0 0 -0 0</pose>
        <geometry>
          <mesh>
            <scale>1 1 1</scale>
            <uri>model://atlas_hydra/meshes/r_hand.DAE</uri>
          </mesh>
        </geometry>
        <surface>
          <contact>
            <ode/>
          </contact>
          <friction>
            <ode/>
          </friction>
        </surface>
        <surface>
          <contact>
            <ode/>
          </contact>
          <friction>
            <ode>
              <mu>0.9</mu>
              <mu2>0.9</mu2>
            </ode>
          </friction>
        </surface>
      </collision>
      <collision name='r_hand_collision_right_palm'>
        <pose>0.0142104 -0.20416 0.04976 3.14157 1.57079 0.670783</pose>
        <geometry>
          <cylinder>
            <length>0.1</length>
            <radius>0.013</radius>
          </cylinder>
        </geometry>
        <surface>
          <contact>
            <ode/>
          </contact>
          <friction>
            <ode/>
          </friction>
        </surface>
        <surface>
          <contact>
            <ode/>
          </contact>
          <friction>
            <ode>
              <mu>0.9</mu>
              <mu2>0.9</mu2>
            </ode>
          </friction>
        </surface>
        <max_contacts>6</max_contacts>
        <surface>
          <contact>
            <ode>
              <kp>1e+06</kp>
              <kd>1</kd>
              <max_vel>0.01</max_vel>
              <min_depth>0</min_depth>
            </ode>
          </contact>
          <friction>
            <ode>
              <mu>1.1</mu>
              <mu2>1.1</mu2>
            </ode>
          </friction>
        </surface>
      </collision>
      <collision name='r_hand_collision_right_palm_1'>
        <pose>0.0062104 -0.19916 0.03276 0.41 2.77556e-17 -2.47079</pose>
        <geometry>
          <box>
            <size>0.09 0.035 0.05</size>
          </box>
        </geometry>
        <surface>
          <contact>
            <ode/>
          </contact>
          <friction>
            <ode/>
          </friction>
        </surface>
        <surface>
          <contact>
            <ode/>
          </contact>
          <friction>
            <ode>
              <mu>0.9</mu>
              <mu2>0.9</mu2>
            </ode>
          </friction>
        </surface>
      </collision>
      <collision name='r_hand_collision_right_palm_2'>
        <pose>-0.00178987 -0.15516 0.00676 -3.14158 1.57079 1.57082</pose>
        <geometry>
          <cylinder>
            <length>0.05</length>
            <radius>0.038</radius>
          </cylinder>
        </geometry>
        <surface>
          <contact>
            <ode/>
          </contact>
          <friction>
            <ode/>
          </friction>
        </surface>
        <surface>
          <contact>
            <ode/>
          </contact>
          <friction>
            <ode>
              <mu>0.9</mu>
              <mu2>0.9</mu2>
            </ode>
          </friction>
        </surface>
      </collision>
      <collision name='r_hand_collision_right_palm_3'>
        <pose>-0.0117893 -0.24516 0.00676 0 0 -1.20079</pose>
        <geometry>
          <box>
            <size>0.09 0.03 0.06</size>
          </box>
        </geometry>
        <surface>
          <contact>
            <ode/>
          </contact>
          <friction>
            <ode/>
          </friction>
        </surface>
        <surface>
          <contact>
            <ode/>
          </contact>
          <friction>
            <ode>
              <mu>0.9</mu>
              <mu2>0.9</mu2>
            </ode>
          </friction>
        </surface>
      </collision>
      <collision name='r_hand_collision_right_palm_4'>
        <pose>0.0182106 -0.22516 0.00676 0 0 -1.20079</pose>
        <geometry>
          <box>
            <size>0.09 0.03 0.06</size>
          </box>
        </geometry>
        <surface>
          <contact>
            <ode/>
          </contact>
          <friction>
            <ode/>
          </friction>
        </surface>
        <surface>
          <contact>
            <ode/>
          </contact>
          <friction>
            <ode>
              <mu>0.9</mu>
              <mu2>0.9</mu2>
            </ode>
          </friction>
        </surface>
      </collision>
      <collision name='r_hand_collision_right_palm_5'>
        <pose>0.0482104 -0.19516 0.00676 0 0 -1.20079</pose>
        <geometry>
          <box>
            <size>0.09 0.03 0.06</size>
          </box>
        </geometry>
        <surface>
          <contact>
            <ode/>
          </contact>
          <friction>
            <ode/>
          </friction>
        </surface>
        <surface>
          <contact>
            <ode/>
          </contact>
          <friction>
            <ode>
              <mu>0.9</mu>
              <mu2>0.9</mu2>
            </ode>
          </friction>
        </surface>
      </collision>
      <collision name='r_hand_collision_right_palm_6'>
        <pose>-0.0417897 -0.17916 0.00676 0 0 -0.78079</pose>
        <geometry>
          <box>
            <size>0.09 0.03 0.06</size>
          </box>
        </geometry>
        <surface>
          <contact>
            <ode/>
          </contact>
          <friction>
            <ode/>
          </friction>
        </surface>
        <surface>
          <contact>
            <ode/>
          </contact>
          <friction>
            <ode>
              <mu>0.9</mu>
              <mu2>0.9</mu2>
            </ode>
          </friction>
        </surface>
      </collision>
      <visual name='r_hand_visual'>
        <pose>0 0 0 0 -0 0</pose>
        <geometry>
          <mesh>
            <scale>1 1 1</scale>
            <uri>model://atlas_hydra/meshes/r_hand.DAE</uri>
          </mesh>
        </geometry>
      </visual>
      <visual name='r_hand_visual_right_palm'>
        <pose>0.0142104 -0.20416 0.04976 3.14157 1.57079 0.670783</pose>
        <geometry>
          <cylinder>
            <length>0.1</length>
            <radius>0.013</radius>
          </cylinder>
        </geometry>
        <material>
          <script>
            <name>Gazebo/FlatBlack</name>
            <uri>__default__</uri>
          </script>
        </material>
      </visual>
      <visual name='r_hand_visual_right_palm_1'>
        <pose>0.0062104 -0.19916 0.03276 0.41 2.77556e-17 -2.47079</pose>
        <geometry>
          <box>
            <size>0.09 0.035 0.05</size>
          </box>
        </geometry>
        <material>
          <script>
            <name>Gazebo/FlatBlack</name>
            <uri>__default__</uri>
          </script>
        </material>
      </visual>
      <visual name='r_hand_visual_right_palm_2'>
        <pose>-0.00178987 -0.15516 0.00676 -3.14158 1.57079 1.57082</pose>
        <geometry>
          <cylinder>
            <length>0.05</length>
            <radius>0.038</radius>
          </cylinder>
        </geometry>
        <material>
          <script>
            <name>Gazebo/FlatBlack</name>
            <uri>__default__</uri>
          </script>
        </material>
      </visual>
      <visual name='r_hand_visual_right_palm_3'>
        <pose>-0.0117893 -0.24516 0.00676 0 0 -1.20079</pose>
        <geometry>
          <box>
            <size>0.09 0.03 0.06</size>
          </box>
        </geometry>
        <material>
          <script>
            <name>Gazebo/FlatBlack</name>
            <uri>__default__</uri>
          </script>
        </material>
      </visual>
      <visual name='r_hand_visual_right_palm_4'>
        <pose>0.0182106 -0.22516 0.00676 0 0 -1.20079</pose>
        <geometry>
          <box>
            <size>0.09 0.03 0.06</size>
          </box>
        </geometry>
        <material>
          <script>
            <name>Gazebo/FlatBlack</name>
            <uri>__default__</uri>
          </script>
        </material>
      </visual>
      <visual name='r_hand_visual_right_palm_5'>
        <pose>0.0482104 -0.19516 0.00676 0 0 -1.20079</pose>
        <geometry>
          <box>
            <size>0.09 0.03 0.06</size>
          </box>
        </geometry>
        <material>
          <script>
            <name>Gazebo/FlatBlack</name>
            <uri>__default__</uri>
          </script>
        </material>
      </visual>
      <visual name='r_hand_visual_right_palm_6'>
        <pose>-0.0417897 -0.17916 0.00676 0 0 -0.78079</pose>
        <geometry>
          <box>
            <size>0.09 0.03 0.06</size>
          </box>
        </geometry>
        <material>
          <script>
            <name>Gazebo/FlatBlack</name>
            <uri>__default__</uri>
          </script>
        </material>
      </visual>
      <visual name='r_hand_visual_right_palm_left_camera_frame'>
        <pose>0.0120447 -0.203537 0.03676 -2.47079 -1.57079 -1.57079</pose>
        <geometry>
          <box>
            <size>0.003 0.01 0.007</size>
          </box>
        </geometry>
        <material>
          <script>
            <name>Gazebo/FlatBlack</name>
            <uri>__default__</uri>
          </script>
        </material>
      </visual>
      <visual name='r_hand_visual_right_palm_right_camera_frame'>
        <pose>0.0433776 -0.178673 0.03676 -2.47079 -1.57079 -1.57079</pose>
        <geometry>
          <box>
            <size>0.003 0.01 0.007</size>
          </box>
        </geometry>
        <material>
          <script>
            <name>Gazebo/FlatBlack</name>
            <uri>__default__</uri>
          </script>
        </material>
      </visual>
    </link>
    <joint name='r_arm_wrx' type='revolute'>
      <child>r_hand</child>
      <parent>r_farm</parent>
      <axis>
        <xyz>1 0 0</xyz>
        <limit>
          <!--
          <lower>-1.1781</lower>
          <upper>1.1781</upper>
-->
          <effort>60</effort>
          <velocity>12</velocity>
        </limit>
        <dynamics>
          <damping>0.1</damping>
        </dynamics>
      </axis>
      <physics>
        <provide_feedback>1</provide_feedback>
        <ode>
          <provide_feedback>1</provide_feedback>
          <limit>
            <cfm>0</cfm>
            <erp>0.2</erp>
          </limit>
          <implicit_spring_damper>1</implicit_spring_damper>
        </ode>
      </physics>
    </joint>
    <link name='right_f0_0'>
      <pose>0.0501209 -1.16617 0.55221 0 0 -1.27079</pose>
      <inertial>
        <pose>0 0 0 0 -0 0</pose>
        <mass>0.106</mass>
        <inertia>
          <ixx>1.1925e-03</ixx>
          <ixy>0</ixy>
          <ixz>0</ixz>
          <iyy>0.011505</iyy>
          <iyz>0</iyz>
          <izz>0.011505</izz>
        </inertia>
      </inertial>
      <collision name='right_f0_0_collision'>
        <pose>0 0 0.003 0 -0 0</pose>
        <geometry>
          <cylinder>
            <length>0.023</length>
            <radius>0.015</radius>
          </cylinder>
        </geometry>
        <max_contacts>1</max_contacts>
        <surface>
          <contact>
            <ode>
              <kp>1e+06</kp>
              <kd>10</kd>
              <max_vel>0.01</max_vel>
              <min_depth>0</min_depth>
            </ode>
          </contact>
          <friction>
            <ode>
              <mu>1.1</mu>
              <mu2>1.1</mu2>
            </ode>
          </friction>
        </surface>
      </collision>
      <collision name='right_f0_0_collision_right_f0_0_other'>
        <pose>0.011 0 0.003 1.5708 -0 0</pose>
        <geometry>
          <cylinder>
            <length>0.023</length>
            <radius>0.01</radius>
          </cylinder>
        </geometry>
        <max_contacts>1</max_contacts>
        <surface>
          <contact>
            <ode>
              <kp>1e+06</kp>
              <kd>10</kd>
              <max_vel>0.01</max_vel>
              <min_depth>0</min_depth>
            </ode>
          </contact>
          <friction>
            <ode>
              <mu>1.1</mu>
              <mu2>1.1</mu2>
            </ode>
          </friction>
        </surface>
      </collision>
      <visual name='right_f0_0_visual'>
        <pose>0 0 0.003 0 -0 0</pose>
        <geometry>
          <cylinder>
            <length>0.023</length>
            <radius>0.015</radius>
          </cylinder>
        </geometry>
        <material>
          <script>
            <name>Gazebo/FlatBlack</name>
            <uri>__default__</uri>
          </script>
        </material>
      </visual>
      <visual name='right_f0_0_visual_right_f0_0_1'>
        <pose>0.011 0 0.003 1.5708 -0 0</pose>
        <geometry>
          <cylinder>
            <length>0.023</length>
            <radius>0.01</radius>
          </cylinder>
        </geometry>
        <material>
          <script>
            <name>Gazebo/FlatBlack</name>
            <uri>__default__</uri>
          </script>
        </material>
      </visual>
      <gravity>1</gravity>
      <velocity_decay>
        <linear>0</linear>
        <angular>0</angular>
      </velocity_decay>
      <self_collide>0</self_collide>
    </link>
    <joint name='right_f0_j0' type='revolute'>
      <child>right_f0_0</child>
      <parent>r_hand</parent>
      <axis>
        <xyz>0 0 1</xyz>
        <limit>
          <lower>0</lower>
          <upper>0</upper>
          <effort>11</effort>
          <velocity>-1</velocity>
        </limit>
        <dynamics>
          <damping>1</damping>
        </dynamics>
      </axis>
      <physics>
        <ode>
          <implicit_spring_damper>1</implicit_spring_damper>
          <limit>
            <cfm>0</cfm>
            <erp>0.2</erp>
          </limit>
        </ode>
      </physics>
    </joint>
    <link name='right_f0_1'>
      <pose>0.0583956 -1.19292 0.55221 1.5708 -2.22045e-16 -1.27079</pose>
      <inertial>
        <pose>0.00697674 0 0 0 -0 0</pose>
        <mass>0.043</mass>
        <inertia>
          <ixx>2.65e-04</ixx>
          <ixy>0</ixy>
          <ixz>0</ixz>
          <iyy>2.10767e-03</iyy>
          <iyz>0</iyz>
          <izz>2.10767e-03</izz>
        </inertia>
      </inertial>
      <collision name='right_f0_1_collision'>
        <pose>0.024 0 0 3.14159 1.57079 3.14159</pose>
        <geometry>
          <cylinder>
            <length>0.067</length>
            <radius>0.01</radius>
          </cylinder>
        </geometry>
        <max_contacts>1</max_contacts>
        <surface>
          <contact>
            <ode>
              <kp>1e+06</kp>
              <kd>10</kd>
              <max_vel>0.01</max_vel>
              <min_depth>0</min_depth>
            </ode>
          </contact>
          <friction>
            <ode>
              <mu>1.1</mu>
              <mu2>1.1</mu2>
            </ode>
          </friction>
        </surface>
      </collision>
      <visual name='right_f0_1_visual'>
        <pose>0.024 0 0 3.14159 1.57079 3.14159</pose>
        <geometry>
          <cylinder>
            <length>0.067</length>
            <radius>0.01</radius>
          </cylinder>
        </geometry>
        <material>
          <script>
            <name>Gazebo/FlatBlack</name>
            <uri>__default__</uri>
          </script>
        </material>
      </visual>
      <gravity>1</gravity>
      <velocity_decay>
        <linear>0</linear>
        <angular>0</angular>
      </velocity_decay>
      <self_collide>0</self_collide>
    </link>
    <joint name='right_f0_j1' type='revolute'>
      <child>right_f0_1</child>
      <parent>right_f0_0</parent>
      <axis>
        <xyz>-0.955335 -0.295526 4.89672e-12</xyz>
        <limit>
          <lower>-1.5708</lower>
          <upper>1.5708</upper>
          <effort>28</effort>
          <velocity>-1</velocity>
        </limit>
        <dynamics>
          <damping>1</damping>
        </dynamics>
      </axis>
      <physics>
        <ode>
          <implicit_spring_damper>1</implicit_spring_damper>
          <limit>
            <cfm>0</cfm>
            <erp>0.2</erp>
          </limit>
        </ode>
      </physics>
    </joint>
    <link name='right_f0_2'>
      <pose>0.0731719 -1.24069 0.55221 1.5708 -2.22045e-16 -1.27079</pose>
      <inertial>
        <pose>0.00930233 0 0 0 -0 0</pose>
        <mass>0.043</mass>
        <inertia>
          <ixx>2.3365e-04</ixx>
          <ixy>0</ixy>
          <ixz>0</ixz>
          <iyy>2.28821e-03</iyy>
          <iyz>0</iyz>
          <izz>2.28821e-03</izz>
        </inertia>
      </inertial>
      <collision name='right_f0_2_collision'>
        <pose>0.024 0 0 3.14159 1.57079 3.14159</pose>
        <geometry>
          <cylinder>
            <length>0.057</length>
            <radius>0.009</radius>
          </cylinder>
        </geometry>
        <max_contacts>1</max_contacts>
        <surface>
          <contact>
            <ode>
              <kp>1e+06</kp>
              <kd>10</kd>
              <max_vel>0.01</max_vel>
              <min_depth>0</min_depth>
            </ode>
          </contact>
          <friction>
            <ode>
              <mu>1.1</mu>
              <mu2>1.1</mu2>
            </ode>
          </friction>
        </surface>
      </collision>
      <collision name='right_f0_2_collision_right_f0_2_other'>
        <pose>0.052 0 0 0 -0 0</pose>
        <geometry>
          <sphere>
            <radius>0.009</radius>
          </sphere>
        </geometry>
        <max_contacts>1</max_contacts>
        <surface>
          <contact>
            <ode>
              <kp>1e+06</kp>
              <kd>10</kd>
              <max_vel>0.01</max_vel>
              <min_depth>0</min_depth>
            </ode>
          </contact>
          <friction>
            <ode>
              <mu>1.1</mu>
              <mu2>1.1</mu2>
            </ode>
          </friction>
        </surface>
      </collision>
      <visual name='right_f0_2_visual'>
        <pose>0.024 0 0 3.14159 1.57079 3.14159</pose>
        <geometry>
          <cylinder>
            <length>0.057</length>
            <radius>0.009</radius>
          </cylinder>
        </geometry>
        <material>
          <script>
            <name>Gazebo/FlatBlack</name>
            <uri>__default__</uri>
          </script>
        </material>
      </visual>
      <visual name='right_f0_2_visual_right_f0_2_1'>
        <pose>0.052 0 0 0 -0 0</pose>
        <geometry>
          <sphere>
            <radius>0.009</radius>
          </sphere>
        </geometry>
        <material>
          <script>
            <name>Gazebo/FlatBlack</name>
            <uri>__default__</uri>
          </script>
        </material>
      </visual>
      <gravity>1</gravity>
      <velocity_decay>
        <linear>0</linear>
        <angular>0</angular>
      </velocity_decay>
      <self_collide>0</self_collide>
    </link>
    <joint name='right_f0_j2' type='revolute'>
      <child>right_f0_2</child>
      <parent>right_f0_1</parent>
      <axis>
        <xyz>-0.955335 -0.295526 4.89672e-12</xyz>
        <limit>
          <lower>-1.5708</lower>
          <upper>1.5708</upper>
          <effort>28</effort>
          <velocity>-1</velocity>
        </limit>
        <dynamics>
          <damping>1</damping>
        </dynamics>
      </axis>
      <physics>
        <ode>
          <implicit_spring_damper>1</implicit_spring_damper>
          <limit>
            <cfm>0</cfm>
            <erp>0.2</erp>
          </limit>
        </ode>
      </physics>
    </joint>
    <link name='right_f1_0'>
      <pose>0.0813407 -1.14117 0.55221 0 0 -1.27079</pose>
      <inertial>
        <pose>0 0 0 0 -0 0</pose>
        <mass>0.106</mass>
        <inertia>
          <ixx>1.1925e-03</ixx>
          <ixy>0</ixy>
          <ixz>0</ixz>
          <iyy>0.011505</iyy>
          <iyz>0</iyz>
          <izz>0.011505</izz>
        </inertia>
      </inertial>
      <collision name='right_f1_0_collision'>
        <pose>0 0 0.003 0 -0 0</pose>
        <geometry>
          <cylinder>
            <length>0.023</length>
            <radius>0.015</radius>
          </cylinder>
        </geometry>
        <max_contacts>1</max_contacts>
        <surface>
          <contact>
            <ode>
              <kp>1e+06</kp>
              <kd>10</kd>
              <max_vel>0.01</max_vel>
              <min_depth>0</min_depth>
            </ode>
          </contact>
          <friction>
            <ode>
              <mu>1.1</mu>
              <mu2>1.1</mu2>
            </ode>
          </friction>
        </surface>
      </collision>
      <collision name='right_f1_0_collision_right_f1_0_other'>
        <pose>0.011 0 0.003 1.5708 -0 0</pose>
        <geometry>
          <cylinder>
            <length>0.023</length>
            <radius>0.01</radius>
          </cylinder>
        </geometry>
        <max_contacts>1</max_contacts>
        <surface>
          <contact>
            <ode>
              <kp>1e+06</kp>
              <kd>10</kd>
              <max_vel>0.01</max_vel>
              <min_depth>0</min_depth>
            </ode>
          </contact>
          <friction>
            <ode>
              <mu>1.1</mu>
              <mu2>1.1</mu2>
            </ode>
          </friction>
        </surface>
      </collision>
      <visual name='right_f1_0_visual'>
        <pose>0 0 0.003 0 -0 0</pose>
        <geometry>
          <cylinder>
            <length>0.023</length>
            <radius>0.015</radius>
          </cylinder>
        </geometry>
        <material>
          <script>
            <name>Gazebo/FlatBlack</name>
            <uri>__default__</uri>
          </script>
        </material>
      </visual>
      <visual name='right_f1_0_visual_right_f1_0_1'>
        <pose>0.011 0 0.003 1.5708 -0 0</pose>
        <geometry>
          <cylinder>
            <length>0.023</length>
            <radius>0.01</radius>
          </cylinder>
        </geometry>
        <material>
          <script>
            <name>Gazebo/FlatBlack</name>
            <uri>__default__</uri>
          </script>
        </material>
      </visual>
      <gravity>1</gravity>
      <velocity_decay>
        <linear>0</linear>
        <angular>0</angular>
      </velocity_decay>
      <self_collide>0</self_collide>
    </link>
    <joint name='right_f1_j0' type='revolute'>
      <child>right_f1_0</child>
      <parent>r_hand</parent>
      <axis>
        <xyz>0 0 1</xyz>
        <limit>
          <lower>0</lower>
          <upper>0</upper>
          <effort>11</effort>
          <velocity>-1</velocity>
        </limit>
        <dynamics>
          <damping>1</damping>
        </dynamics>
      </axis>
      <physics>
        <ode>
          <implicit_spring_damper>1</implicit_spring_damper>
          <limit>
            <cfm>0</cfm>
            <erp>0.2</erp>
          </limit>
        </ode>
      </physics>
    </joint>
    <link name='right_f1_1'>
      <pose>0.0896155 -1.16792 0.55221 1.5708 -2.22045e-16 -1.27079</pose>
      <inertial>
        <pose>0.00697674 0 0 0 -0 0</pose>
        <mass>0.043</mass>
        <inertia>
          <ixx>2.65e-04</ixx>
          <ixy>0</ixy>
          <ixz>0</ixz>
          <iyy>2.10767e-03</iyy>
          <iyz>0</iyz>
          <izz>2.10767e-03</izz>
        </inertia>
      </inertial>
      <collision name='right_f1_1_collision'>
        <pose>0.024 0 0 3.14159 1.57079 3.14159</pose>
        <geometry>
          <cylinder>
            <length>0.067</length>
            <radius>0.01</radius>
          </cylinder>
        </geometry>
        <max_contacts>1</max_contacts>
        <surface>
          <contact>
            <ode>
              <kp>1e+06</kp>
              <kd>10</kd>
              <max_vel>0.01</max_vel>
              <min_depth>0</min_depth>
            </ode>
          </contact>
          <friction>
            <ode>
              <mu>1.1</mu>
              <mu2>1.1</mu2>
            </ode>
          </friction>
        </surface>
      </collision>
      <visual name='right_f1_1_visual'>
        <pose>0.024 0 0 3.14159 1.57079 3.14159</pose>
        <geometry>
          <cylinder>
            <length>0.067</length>
            <radius>0.01</radius>
          </cylinder>
        </geometry>
        <material>
          <script>
            <name>Gazebo/FlatBlack</name>
            <uri>__default__</uri>
          </script>
        </material>
      </visual>
      <gravity>1</gravity>
      <velocity_decay>
        <linear>0</linear>
        <angular>0</angular>
      </velocity_decay>
      <self_collide>0</self_collide>
    </link>
    <joint name='right_f1_j1' type='revolute'>
      <child>right_f1_1</child>
      <parent>right_f1_0</parent>
      <axis>
        <xyz>-0.955335 -0.295526 4.89672e-12</xyz>
        <limit>
          <lower>-1.5708</lower>
          <upper>1.5708</upper>
          <effort>28</effort>
          <velocity>-1</velocity>
        </limit>
        <dynamics>
          <damping>1</damping>
        </dynamics>
      </axis>
      <physics>
        <ode>
          <implicit_spring_damper>1</implicit_spring_damper>
          <limit>
            <cfm>0</cfm>
            <erp>0.2</erp>
          </limit>
        </ode>
      </physics>
    </joint>
    <link name='right_f1_2'>
      <pose>0.104392 -1.21569 0.55221 1.5708 -2.22045e-16 -1.27079</pose>
      <inertial>
        <pose>0.00930233 0 0 0 -0 0</pose>
        <mass>0.043</mass>
        <inertia>
          <ixx>2.3365e-04</ixx>
          <ixy>0</ixy>
          <ixz>0</ixz>
          <iyy>2.28821e-03</iyy>
          <iyz>0</iyz>
          <izz>2.28821e-03</izz>
        </inertia>
      </inertial>
      <collision name='right_f1_2_collision'>
        <pose>0.024 0 0 3.14159 1.57079 3.14159</pose>
        <geometry>
          <cylinder>
            <length>0.057</length>
            <radius>0.009</radius>
          </cylinder>
        </geometry>
        <max_contacts>1</max_contacts>
        <surface>
          <contact>
            <ode>
              <kp>1e+06</kp>
              <kd>10</kd>
              <max_vel>0.01</max_vel>
              <min_depth>0</min_depth>
            </ode>
          </contact>
          <friction>
            <ode>
              <mu>1.1</mu>
              <mu2>1.1</mu2>
            </ode>
          </friction>
        </surface>
      </collision>
      <collision name='right_f1_2_collision_right_f1_2_other'>
        <pose>0.052 0 0 0 -0 0</pose>
        <geometry>
          <sphere>
            <radius>0.009</radius>
          </sphere>
        </geometry>
        <max_contacts>1</max_contacts>
        <surface>
          <contact>
            <ode>
              <kp>1e+06</kp>
              <kd>10</kd>
              <max_vel>0.01</max_vel>
              <min_depth>0</min_depth>
            </ode>
          </contact>
          <friction>
            <ode>
              <mu>1.1</mu>
              <mu2>1.1</mu2>
            </ode>
          </friction>
        </surface>
      </collision>
      <visual name='right_f1_2_visual'>
        <pose>0.024 0 0 3.14159 1.57079 3.14159</pose>
        <geometry>
          <cylinder>
            <length>0.057</length>
            <radius>0.009</radius>
          </cylinder>
        </geometry>
        <material>
          <script>
            <name>Gazebo/FlatBlack</name>
            <uri>__default__</uri>
          </script>
        </material>
      </visual>
      <visual name='right_f1_2_visual_right_f1_2_1'>
        <pose>0.052 0 0 0 -0 0</pose>
        <geometry>
          <sphere>
            <radius>0.009</radius>
          </sphere>
        </geometry>
        <material>
          <script>
            <name>Gazebo/FlatBlack</name>
            <uri>__default__</uri>
          </script>
        </material>
      </visual>
      <gravity>1</gravity>
      <velocity_decay>
        <linear>0</linear>
        <angular>0</angular>
      </velocity_decay>
      <self_collide>0</self_collide>
    </link>
    <joint name='right_f1_j2' type='revolute'>
      <child>right_f1_2</child>
      <parent>right_f1_1</parent>
      <axis>
        <xyz>-0.955335 -0.295526 4.89672e-12</xyz>
        <limit>
          <lower>-1.5708</lower>
          <upper>1.5708</upper>
          <effort>28</effort>
          <velocity>-1</velocity>
        </limit>
        <dynamics>
          <damping>1</damping>
        </dynamics>
      </axis>
      <physics>
        <ode>
          <implicit_spring_damper>1</implicit_spring_damper>
          <limit>
            <cfm>0</cfm>
            <erp>0.2</erp>
          </limit>
        </ode>
      </physics>
    </joint>
    <link name='right_f2_0'>
      <pose>0.112571 -1.11617 0.55221 0 0 -1.27079</pose>
      <inertial>
        <pose>0 0 0 0 -0 0</pose>
        <mass>0.106</mass>
        <inertia>
          <ixx>1.1925e-03</ixx>
          <ixy>0</ixy>
          <ixz>0</ixz>
          <iyy>0.011505</iyy>
          <iyz>0</iyz>
          <izz>0.011505</izz>
        </inertia>
      </inertial>
      <collision name='right_f2_0_collision'>
        <pose>0 0 0.003 0 -0 0</pose>
        <geometry>
          <cylinder>
            <length>0.023</length>
            <radius>0.015</radius>
          </cylinder>
        </geometry>
        <max_contacts>1</max_contacts>
        <surface>
          <contact>
            <ode>
              <kp>1e+06</kp>
              <kd>10</kd>
              <max_vel>0.01</max_vel>
              <min_depth>0</min_depth>
            </ode>
          </contact>
          <friction>
            <ode>
              <mu>1.1</mu>
              <mu2>1.1</mu2>
            </ode>
          </friction>
        </surface>
      </collision>
      <collision name='right_f2_0_collision_right_f2_0_other'>
        <pose>0.011 0 0.003 1.5708 -0 0</pose>
        <geometry>
          <cylinder>
            <length>0.023</length>
            <radius>0.01</radius>
          </cylinder>
        </geometry>
        <max_contacts>1</max_contacts>
        <surface>
          <contact>
            <ode>
              <kp>1e+06</kp>
              <kd>10</kd>
              <max_vel>0.01</max_vel>
              <min_depth>0</min_depth>
            </ode>
          </contact>
          <friction>
            <ode>
              <mu>1.1</mu>
              <mu2>1.1</mu2>
            </ode>
          </friction>
        </surface>
      </collision>
      <visual name='right_f2_0_visual'>
        <pose>0 0 0.003 0 -0 0</pose>
        <geometry>
          <cylinder>
            <length>0.023</length>
            <radius>0.015</radius>
          </cylinder>
        </geometry>
        <material>
          <script>
            <name>Gazebo/FlatBlack</name>
            <uri>__default__</uri>
          </script>
        </material>
      </visual>
      <visual name='right_f2_0_visual_right_f2_0_1'>
        <pose>0.011 0 0.003 1.5708 -0 0</pose>
        <geometry>
          <cylinder>
            <length>0.023</length>
            <radius>0.01</radius>
          </cylinder>
        </geometry>
        <material>
          <script>
            <name>Gazebo/FlatBlack</name>
            <uri>__default__</uri>
          </script>
        </material>
      </visual>
      <gravity>1</gravity>
      <velocity_decay>
        <linear>0</linear>
        <angular>0</angular>
      </velocity_decay>
      <self_collide>0</self_collide>
    </link>
    <joint name='right_f2_j0' type='revolute'>
      <child>right_f2_0</child>
      <parent>r_hand</parent>
      <axis>
        <xyz>0 0 1</xyz>
        <limit>
          <lower>0</lower>
          <upper>0</upper>
          <effort>11</effort>
          <velocity>-1</velocity>
        </limit>
        <dynamics>
          <damping>1</damping>
        </dynamics>
      </axis>
      <physics>
        <ode>
          <implicit_spring_damper>1</implicit_spring_damper>
          <limit>
            <cfm>0</cfm>
            <erp>0.2</erp>
          </limit>
        </ode>
      </physics>
    </joint>
    <link name='right_f2_1'>
      <pose>0.120845 -1.14292 0.55221 1.5708 -2.22045e-16 -1.27079</pose>
      <inertial>
        <pose>0.00697674 0 0 0 -0 0</pose>
        <mass>0.043</mass>
        <inertia>
          <ixx>2.65e-04</ixx>
          <ixy>0</ixy>
          <ixz>0</ixz>
          <iyy>2.10767e-03</iyy>
          <iyz>0</iyz>
          <izz>2.10767e-03</izz>
        </inertia>
      </inertial>
      <collision name='right_f2_1_collision'>
        <pose>0.024 0 0 3.14159 1.57079 3.14159</pose>
        <geometry>
          <cylinder>
            <length>0.067</length>
            <radius>0.01</radius>
          </cylinder>
        </geometry>
        <max_contacts>1</max_contacts>
        <surface>
          <contact>
            <ode>
              <kp>1e+06</kp>
              <kd>10</kd>
              <max_vel>0.01</max_vel>
              <min_depth>0</min_depth>
            </ode>
          </contact>
          <friction>
            <ode>
              <mu>1.1</mu>
              <mu2>1.1</mu2>
            </ode>
          </friction>
        </surface>
      </collision>
      <visual name='right_f2_1_visual'>
        <pose>0.024 0 0 3.14159 1.57079 3.14159</pose>
        <geometry>
          <cylinder>
            <length>0.067</length>
            <radius>0.01</radius>
          </cylinder>
        </geometry>
        <material>
          <script>
            <name>Gazebo/FlatBlack</name>
            <uri>__default__</uri>
          </script>
        </material>
      </visual>
      <gravity>1</gravity>
      <velocity_decay>
        <linear>0</linear>
        <angular>0</angular>
      </velocity_decay>
      <self_collide>0</self_collide>
    </link>
    <joint name='right_f2_j1' type='revolute'>
      <child>right_f2_1</child>
      <parent>right_f2_0</parent>
      <axis>
        <xyz>-0.955335 -0.295526 4.89672e-12</xyz>
        <limit>
          <lower>-1.5708</lower>
          <upper>1.5708</upper>
          <effort>28</effort>
          <velocity>-1</velocity>
        </limit>
        <dynamics>
          <damping>1</damping>
        </dynamics>
      </axis>
      <physics>
        <ode>
          <implicit_spring_damper>1</implicit_spring_damper>
          <limit>
            <cfm>0</cfm>
            <erp>0.2</erp>
          </limit>
        </ode>
      </physics>
    </joint>
    <link name='right_f2_2'>
      <pose>0.135622 -1.19069 0.55221 1.5708 -2.22045e-16 -1.27079</pose>
      <inertial>
        <pose>0.00930233 0 0 0 -0 0</pose>
        <mass>0.043</mass>
        <inertia>
          <ixx>2.3365e-04</ixx>
          <ixy>0</ixy>
          <ixz>0</ixz>
          <iyy>2.28821e-03</iyy>
          <iyz>0</iyz>
          <izz>2.28821e-03</izz>
        </inertia>
      </inertial>
      <collision name='right_f2_2_collision'>
        <pose>0.024 0 0 3.14159 1.57079 3.14159</pose>
        <geometry>
          <cylinder>
            <length>0.057</length>
            <radius>0.009</radius>
          </cylinder>
        </geometry>
        <max_contacts>1</max_contacts>
        <surface>
          <contact>
            <ode>
              <kp>1e+06</kp>
              <kd>10</kd>
              <max_vel>0.01</max_vel>
              <min_depth>0</min_depth>
            </ode>
          </contact>
          <friction>
            <ode>
              <mu>1.1</mu>
              <mu2>1.1</mu2>
            </ode>
          </friction>
        </surface>
      </collision>
      <collision name='right_f2_2_collision_right_f2_2_other'>
        <pose>0.052 0 0 0 -0 0</pose>
        <geometry>
          <sphere>
            <radius>0.009</radius>
          </sphere>
        </geometry>
        <max_contacts>1</max_contacts>
        <surface>
          <contact>
            <ode>
              <kp>1e+06</kp>
              <kd>10</kd>
              <max_vel>0.01</max_vel>
              <min_depth>0</min_depth>
            </ode>
          </contact>
          <friction>
            <ode>
              <mu>1.1</mu>
              <mu2>1.1</mu2>
            </ode>
          </friction>
        </surface>
      </collision>
      <visual name='right_f2_2_visual'>
        <pose>0.024 0 0 3.14159 1.57079 3.14159</pose>
        <geometry>
          <cylinder>
            <length>0.057</length>
            <radius>0.009</radius>
          </cylinder>
        </geometry>
        <material>
          <script>
            <name>Gazebo/FlatBlack</name>
            <uri>__default__</uri>
          </script>
        </material>
      </visual>
      <visual name='right_f2_2_visual_right_f2_2_1'>
        <pose>0.052 0 0 0 -0 0</pose>
        <geometry>
          <sphere>
            <radius>0.009</radius>
          </sphere>
        </geometry>
        <material>
          <script>
            <name>Gazebo/FlatBlack</name>
            <uri>__default__</uri>
          </script>
        </material>
      </visual>
      <gravity>1</gravity>
      <velocity_decay>
        <linear>0</linear>
        <angular>0</angular>
      </velocity_decay>
      <self_collide>0</self_collide>
    </link>
    <joint name='right_f2_j2' type='revolute'>
      <child>right_f2_2</child>
      <parent>right_f2_1</parent>
      <axis>
        <xyz>-0.955335 -0.295526 4.89672e-12</xyz>
        <limit>
          <lower>-1.5708</lower>
          <upper>1.5708</upper>
          <effort>28</effort>
          <velocity>-1</velocity>
        </limit>
        <dynamics>
          <damping>1</damping>
        </dynamics>
      </axis>
      <physics>
        <ode>
          <implicit_spring_damper>1</implicit_spring_damper>
          <limit>
            <cfm>0</cfm>
            <erp>0.2</erp>
          </limit>
        </ode>
      </physics>
    </joint>
    <link name='right_f3_0'>
      <pose>0.00629025 -1.06612 0.56621 -3.14158 -1.57079 -0.785413</pose>
      <inertial>
        <pose>0 0 0 0 -0 0</pose>
        <mass>0.106</mass>
        <inertia>
          <ixx>1.1925e-03</ixx>
          <ixy>0</ixy>
          <ixz>0</ixz>
          <iyy>0.011505</iyy>
          <iyz>0</iyz>
          <izz>0.011505</izz>
        </inertia>
      </inertial>
      <collision name='right_f3_0_collision'>
        <pose>0 0 0.003 0 -0 0</pose>
        <geometry>
          <cylinder>
            <length>0.023</length>
            <radius>0.015</radius>
          </cylinder>
        </geometry>
        <max_contacts>1</max_contacts>
        <surface>
          <contact>
            <ode>
              <kp>1e+06</kp>
              <kd>10</kd>
              <max_vel>0.01</max_vel>
              <min_depth>0</min_depth>
            </ode>
          </contact>
          <friction>
            <ode>
              <mu>1.1</mu>
              <mu2>1.1</mu2>
            </ode>
          </friction>
        </surface>
      </collision>
      <collision name='right_f3_0_collision_right_f3_0_other'>
        <pose>0.011 0 0.003 1.5708 -0 0</pose>
        <geometry>
          <cylinder>
            <length>0.023</length>
            <radius>0.01</radius>
          </cylinder>
        </geometry>
        <max_contacts>1</max_contacts>
        <surface>
          <contact>
            <ode>
              <kp>1e+06</kp>
              <kd>10</kd>
              <max_vel>0.01</max_vel>
              <min_depth>0</min_depth>
            </ode>
          </contact>
          <friction>
            <ode>
              <mu>1.1</mu>
              <mu2>1.1</mu2>
            </ode>
          </friction>
        </surface>
      </collision>
      <visual name='right_f3_0_visual'>
        <pose>0 0 0.003 0 -0 0</pose>
        <geometry>
          <cylinder>
            <length>0.023</length>
            <radius>0.015</radius>
          </cylinder>
        </geometry>
        <material>
          <script>
            <name>Gazebo/FlatBlack</name>
            <uri>__default__</uri>
          </script>
        </material>
      </visual>
      <visual name='right_f3_0_visual_right_f3_0_1'>
        <pose>0.011 0 0.003 1.5708 -0 0</pose>
        <geometry>
          <cylinder>
            <length>0.023</length>
            <radius>0.01</radius>
          </cylinder>
        </geometry>
        <material>
          <script>
            <name>Gazebo/FlatBlack</name>
            <uri>__default__</uri>
          </script>
        </material>
      </visual>
      <gravity>1</gravity>
      <velocity_decay>
        <linear>0</linear>
        <angular>0</angular>
      </velocity_decay>
      <self_collide>0</self_collide>
    </link>
    <joint name='right_f3_j0' type='revolute'>
      <child>right_f3_0</child>
      <parent>r_hand</parent>
      <axis>
        <xyz>0.707107 -0.707106 4.89664e-12</xyz>
        <limit>
          <lower>0</lower>
          <upper>0</upper>
          <effort>11</effort>
          <velocity>-1</velocity>
        </limit>
        <dynamics>
          <damping>1</damping>
        </dynamics>
      </axis>
      <physics>
        <ode>
          <implicit_spring_damper>1</implicit_spring_damper>
          <limit>
            <cfm>0</cfm>
            <erp>0.2</erp>
          </limit>
        </ode>
      </physics>
    </joint>
    <link name='right_f3_1'>
      <pose>0.00629025 -1.06612 0.59421 -1.57077 -1.57079 -0.785423</pose>
      <inertial>
        <pose>0.00697674 0 0 0 -0 0</pose>
        <mass>0.043</mass>
        <inertia>
          <ixx>2.65e-04</ixx>
          <ixy>0</ixy>
          <ixz>0</ixz>
          <iyy>2.10767e-03</iyy>
          <iyz>0</iyz>
          <izz>2.10767e-03</izz>
        </inertia>
      </inertial>
      <collision name='right_f3_1_collision'>
        <pose>0.024 0 0 3.14159 1.57079 3.14159</pose>
        <geometry>
          <cylinder>
            <length>0.067</length>
            <radius>0.01</radius>
          </cylinder>
        </geometry>
        <max_contacts>1</max_contacts>
        <surface>
          <contact>
            <ode>
              <kp>1e+06</kp>
              <kd>10</kd>
              <max_vel>0.01</max_vel>
              <min_depth>0</min_depth>
            </ode>
          </contact>
          <friction>
            <ode>
              <mu>1.1</mu>
              <mu2>1.1</mu2>
            </ode>
          </friction>
        </surface>
      </collision>
      <visual name='right_f3_1_visual'>
        <pose>0.024 0 0 3.14159 1.57079 3.14159</pose>
        <geometry>
          <cylinder>
            <length>0.067</length>
            <radius>0.01</radius>
          </cylinder>
        </geometry>
        <material>
          <script>
            <name>Gazebo/FlatBlack</name>
            <uri>__default__</uri>
          </script>
        </material>
      </visual>
      <gravity>1</gravity>
      <velocity_decay>
        <linear>0</linear>
        <angular>0</angular>
      </velocity_decay>
      <self_collide>0</self_collide>
    </link>
    <joint name='right_f3_j1' type='revolute'>
      <child>right_f3_1</child>
      <parent>right_f3_0</parent>
      <axis>
        <xyz>0.707106 0.707107 -1.11022e-16</xyz>
        <limit>
          <lower>-1.5708</lower>
          <upper>1.5708</upper>
          <effort>28</effort>
          <velocity>-1</velocity>
        </limit>
        <dynamics>
          <damping>1</damping>
        </dynamics>
      </axis>
      <physics>
        <ode>
          <implicit_spring_damper>1</implicit_spring_damper>
          <limit>
            <cfm>0</cfm>
            <erp>0.2</erp>
          </limit>
        </ode>
      </physics>
    </joint>
    <link name='right_f3_2'>
      <pose>0.00629025 -1.06612 0.64421 -1.57077 -1.57079 -0.785423</pose>
      <inertial>
        <pose>0.00930233 0 0 0 -0 0</pose>
        <mass>0.043</mass>
        <inertia>
          <ixx>2.3365e-04</ixx>
          <ixy>0</ixy>
          <ixz>0</ixz>
          <iyy>2.28821e-03</iyy>
          <iyz>0</iyz>
          <izz>2.28821e-03</izz>
        </inertia>
      </inertial>
      <collision name='right_f3_2_collision'>
        <pose>0.024 0 0 3.14159 1.57079 3.14159</pose>
        <geometry>
          <cylinder>
            <length>0.057</length>
            <radius>0.009</radius>
          </cylinder>
        </geometry>
        <max_contacts>1</max_contacts>
        <surface>
          <contact>
            <ode>
              <kp>1e+06</kp>
              <kd>10</kd>
              <max_vel>0.01</max_vel>
              <min_depth>0</min_depth>
            </ode>
          </contact>
          <friction>
            <ode>
              <mu>1.1</mu>
              <mu2>1.1</mu2>
            </ode>
          </friction>
        </surface>
      </collision>
      <collision name='right_f3_2_collision_right_f3_2_other'>
        <pose>0.052 0 0 0 -0 0</pose>
        <geometry>
          <sphere>
            <radius>0.009</radius>
          </sphere>
        </geometry>
        <max_contacts>1</max_contacts>
        <surface>
          <contact>
            <ode>
              <kp>1e+06</kp>
              <kd>10</kd>
              <max_vel>0.01</max_vel>
              <min_depth>0</min_depth>
            </ode>
          </contact>
          <friction>
            <ode>
              <mu>1.1</mu>
              <mu2>1.1</mu2>
            </ode>
          </friction>
        </surface>
      </collision>
      <visual name='right_f3_2_visual'>
        <pose>0.024 0 0 3.14159 1.57079 3.14159</pose>
        <geometry>
          <cylinder>
            <length>0.057</length>
            <radius>0.009</radius>
          </cylinder>
        </geometry>
        <material>
          <script>
            <name>Gazebo/FlatBlack</name>
            <uri>__default__</uri>
          </script>
        </material>
      </visual>
      <visual name='right_f3_2_visual_right_f3_2_1'>
        <pose>0.052 0 0 0 -0 0</pose>
        <geometry>
          <sphere>
            <radius>0.009</radius>
          </sphere>
        </geometry>
        <material>
          <script>
            <name>Gazebo/FlatBlack</name>
            <uri>__default__</uri>
          </script>
        </material>
      </visual>
      <gravity>1</gravity>
      <velocity_decay>
        <linear>0</linear>
        <angular>0</angular>
      </velocity_decay>
      <self_collide>0</self_collide>
    </link>
    <joint name='right_f3_j2' type='revolute'>
      <child>right_f3_2</child>
      <parent>right_f3_1</parent>
      <axis>
        <xyz>0.707106 0.707107 -1.11022e-16</xyz>
        <limit>
          <lower>-1.5708</lower>
          <upper>1.5708</upper>
          <effort>28</effort>
          <velocity>-1</velocity>
        </limit>
        <dynamics>
          <damping>1</damping>
        </dynamics>
      </axis>
      <physics>
        <ode>
          <implicit_spring_damper>1</implicit_spring_damper>
          <limit>
            <cfm>0</cfm>
            <erp>0.2</erp>
          </limit>
        </ode>
      </physics>
    </joint>


    <!--
    <link name='l_uglut'>
      <pose>0 0.089 0 0 -0 0</pose>
      <inertial>
        <pose>0.00529262 -0.00344732 0.00313046 0 -0 0</pose>
        <mass>0.0648</mass>
        <inertia>
          <ixx>0.00074276</ixx>
          <ixy>-3.79607e-08</ixy>
          <ixz>-2.79549e-05</ixz>
          <iyy>0.000688179</iyy>
          <iyz>-3.2735e-08</iyz>
          <izz>0.00041242</izz>
        </inertia>
      </inertial>
      <visual name='l_uglut_visual'>
      <pose>0 0.089 0 0 -0 0</pose>
        <geometry>
          <mesh>
            <scale>1 1 1</scale>
            <uri>model://atlas_hydra/meshes/l_uglut.DAE</uri>
          </mesh>
        </geometry>
      </visual>
    </link>
    <joint name='l_leg_hpz' type='revolute'>
      <child>l_uglut</child>
      <parent>pelvis</parent>
      <axis>
        <xyz>0 0 1</xyz>
        <limit>
          <lower>0</lower>
          <upper>0</upper>
          <effort>110</effort>
          <velocity>12</velocity>
        </limit>
        <dynamics>
          <damping>0.1</damping>
        </dynamics>
      </axis>
      <physics>
        <ode>
          <implicit_spring_damper>1</implicit_spring_damper>
          <limit>
            <cfm>0</cfm>
            <erp>0.2</erp>
          </limit>
        </ode>
      </physics>
    </joint>
    <link name='l_lglut'>
      <pose>0 0.089 0 0 -0 0</pose>
      <inertial>
        <pose>0.0133341 0.0170484 -0.0312052 0 -0 0</pose>
        <mass>0.0866</mass>
        <inertia>
          <ixx>0.000691326</ixx>
          <ixy>-2.24344e-05</ixy>
          <ixz>2.50508e-06</ixz>
          <iyy>0.00126856</iyy>
          <iyz>0.000137862</iyz>
          <izz>0.00106487</izz>
        </inertia>
      </inertial>
      <visual name='l_lglut_visual'>
      <pose>0 0.089 0 0 -0 0</pose>
        <geometry>
          <mesh>
            <scale>1 1 1</scale>
            <uri>model://atlas_hydra/meshes/l_lglut.DAE</uri>
          </mesh>
        </geometry>
      </visual>
      <gravity>1</gravity>
      <velocity_decay>
        <linear>0</linear>
        <angular>0</angular>
      </velocity_decay>
      <self_collide>0</self_collide>
    </link>
    <joint name='l_leg_hpx' type='revolute'>
      <child>l_lglut</child>
      <parent>l_uglut</parent>
      <axis>
        <xyz>1 0 0</xyz>
        <limit>
          <lower>0</lower>
          <upper>0</upper>
          <effort>180</effort>
          <velocity>12</velocity>
        </limit>
        <dynamics>
          <damping>0.1</damping>
        </dynamics>
      </axis>
      <physics>
        <ode>
          <implicit_spring_damper>1</implicit_spring_damper>
          <limit>
            <cfm>0</cfm>
            <erp>0.2</erp>
          </limit>
        </ode>
      </physics>
    </joint>
    <link name='l_uleg'>
      <pose>0.05 0.089 -0.05 0 -0 0</pose>
      <inertial>
        <pose>0 0 -0.21 0 -0 0</pose>
        <mass>.9209</mass>
        <inertia>
          <ixx>0.09</ixx>
          <ixy>0</ixy>
          <ixz>0</ixz>
          <iyy>0.09</iyy>
          <iyz>0</iyz>
          <izz>0.02</izz>
        </inertia>
      </inertial>
      <visual name='l_uleg_visual'>
        <geometry>
          <mesh>
            <scale>1 1 1</scale>
            <uri>model://atlas_hydra/meshes/l_uleg.DAE</uri>
          </mesh>
        </geometry>
      </visual>
      <gravity>1</gravity>
      <velocity_decay>
        <linear>0</linear>
        <angular>0</angular>
      </velocity_decay>
      <self_collide>0</self_collide>
    </link>
    <joint name='l_leg_hpy' type='revolute'>
      <child>l_uleg</child>
      <parent>l_lglut</parent>
      <axis>
        <xyz>0 1 0</xyz>
        <limit>
          <lower>0</lower>
          <upper>0</upper>
          <effort>260</effort>
          <velocity>12</velocity>
        </limit>
        <dynamics>
          <damping>0.1</damping>
        </dynamics>
      </axis>
      <physics>
        <ode>
          <implicit_spring_damper>1</implicit_spring_damper>
          <limit>
            <cfm>0</cfm>
            <erp>0.2</erp>
          </limit>
        </ode>
      </physics>
    </joint>
    <link name='l_lleg'>
      <pose>0 0.089 -0.424 0 -0 0</pose>
      <inertial>
        <pose>0.001 0 -0.187 0 -0 0</pose>
        <mass>.5479</mass>
        <inertia>
          <ixx>0.077</ixx>
          <ixy>0</ixy>
          <ixz>-0.003</ixz>
          <iyy>0.076</iyy>
          <iyz>0</iyz>
          <izz>0.01</izz>
        </inertia>
      </inertial>
      <visual name='l_lleg_visual'>
        <pose>0 0 0 0 -0 0</pose>
        <geometry>
          <mesh>
            <scale>1 1 1</scale>
            <uri>model://atlas_hydra/meshes/l_lleg.DAE</uri>
          </mesh>
        </geometry>
      </visual>
      <gravity>1</gravity>
      <velocity_decay>
        <linear>0</linear>
        <angular>0</angular>
      </velocity_decay>
      <self_collide>0</self_collide>
    </link>
    <joint name='l_leg_kny' type='revolute'>
      <child>l_lleg</child>
      <parent>l_uleg</parent>
      <axis>
        <xyz>0 1 0</xyz>
        <limit>
          <lower>0</lower>
          <upper>0</upper>
          <effort>220</effort>
          <velocity>12</velocity>
        </limit>
        <dynamics>
          <damping>0.1</damping>
        </dynamics>
      </axis>
      <physics>
        <ode>
          <implicit_spring_damper>1</implicit_spring_damper>
          <limit>
            <cfm>0</cfm>
            <erp>0.2</erp>
          </limit>
        </ode>
      </physics>
    </joint>
    <link name='l_talus'>
      <pose>0 0.089 -0.846 0 -0 0</pose>
      <inertial>
        <pose>0 0 0 0 -0 0</pose>
        <mass>0.0125</mass>
        <inertia>
          <ixx>1.01674e-05</ixx>
          <ixy>0</ixy>
          <ixz>0</ixz>
          <iyy>8.42775e-06</iyy>
          <iyz>0</iyz>
          <izz>1.30101e-05</izz>
        </inertia>
      </inertial>
      <visual name='l_talus_visual'>
        <pose>0 0 0 0 -0 0</pose>
        <geometry>
          <mesh>
            <scale>1 1 1</scale>
            <uri>model://atlas_hydra/meshes/l_talus.DAE</uri>
          </mesh>
        </geometry>
      </visual>
      <gravity>1</gravity>
      <velocity_decay>
        <linear>0</linear>
        <angular>0</angular>
      </velocity_decay>
      <self_collide>0</self_collide>
    </link>
    <joint name='l_leg_aky' type='revolute'>
      <child>l_talus</child>
      <parent>l_lleg</parent>
      <axis>
        <xyz>0 1 0</xyz>
        <limit>
          <lower>0</lower>
          <upper>0</upper>
          <effort>700</effort>
          <velocity>12</velocity>
        </limit>
        <dynamics>
          <damping>0.1</damping>
        </dynamics>
      </axis>
      <physics>
        <ode>
          <implicit_spring_damper>1</implicit_spring_damper>
          <limit>
            <cfm>0</cfm>
            <erp>0.2</erp>
          </limit>
        </ode>
      </physics>
    </joint>
    <link name='l_foot'>
      <pose>0 0.089 -0.846 0 -0 0</pose>
      <inertial>
        <pose>0.027 0 -0.067 0 -0 0</pose>
        <mass>.205</mass>
        <inertia>
          <ixx>0.002</ixx>
          <ixy>0</ixy>
          <ixz>0</ixz>
          <iyy>0.007</iyy>
          <iyz>0</iyz>
          <izz>0.008</izz>
        </inertia>
      </inertial>
      <collision name='l_foot_collision'>
        <pose>0 0 0 0 -0 0</pose>
        <geometry>
          <mesh>
            <scale>1 1 1</scale>
            <uri>model://atlas_hydra/meshes/l_foot.DAE</uri>
          </mesh>
        </geometry>
        <surface>
          <contact>
            <ode>
              <kp>1e+06</kp>
              <kd>100</kd>
              <max_vel>1</max_vel>
              <min_depth>0</min_depth>
            </ode>
          </contact>
          <friction>
            <ode>
              <mu>0.1</mu>
              <mu2>0.1</mu2>
              <fdir1>1 0 0</fdir1>
            </ode>
          </friction>
        </surface>
      </collision>

      <visual name='l_foot_visual'>
        <pose>0 0 0 0 -0 0</pose>
        <geometry>
          <mesh>
            <scale>1 1 1</scale>
            <uri>model://atlas_hydra/meshes/l_foot.DAE</uri>
          </mesh>
        </geometry>
      </visual>
    </link>
    <joint name='l_leg_akx' type='revolute'>
      <child>l_foot</child>
      <parent>l_talus</parent>
      <axis>
        <xyz>1 0 0</xyz>
        <limit>
          <lower>0</lower>
          <upper>0</upper>
          <effort>90</effort>
          <velocity>12</velocity>
        </limit>
        <dynamics>
          <damping>0.1</damping>
        </dynamics>
      </axis>
      <physics>
        <provide_feedback>1</provide_feedback>
        <ode>
          <provide_feedback>1</provide_feedback>
          <implicit_spring_damper>1</implicit_spring_damper>
          <limit>
            <cfm>0</cfm>
            <erp>0.2</erp>
          </limit>
        </ode>
      </physics>
    </joint>
    <link name='r_uglut'>
      <pose>0 -0.089 0 0 -0 0</pose>
      <inertial>
        <pose>0.00529262 0.00344732 0.00313046 0 -0 0</pose>
        <mass>0.0648</mass>
        <inertia>
          <ixx>0.00074276</ixx>
          <ixy>3.79607e-08</ixy>
          <ixz>-2.79549e-05</ixz>
          <iyy>0.000688179</iyy>
          <iyz>3.2735e-08</iyz>
          <izz>0.00041242</izz>
        </inertia>
      </inertial>

      <visual name='r_uglut_visual'>
        <pose>0 0 0 0 -0 0</pose>
        <geometry>
          <mesh>
            <scale>1 1 1</scale>
            <uri>model://atlas_hydra/meshes/r_uglut.DAE</uri>
          </mesh>
        </geometry>
      </visual>
      <gravity>1</gravity>
      <velocity_decay>
        <linear>0</linear>
        <angular>0</angular>
      </velocity_decay>
      <self_collide>0</self_collide>
    </link>
    <joint name='r_leg_hpz' type='revolute'>
      <child>r_uglut</child>
      <parent>pelvis</parent>
      <axis>
        <xyz>0 0 1</xyz>
        <limit>
          <lower>0</lower>
          <upper>0</upper>
          <effort>110</effort>
          <velocity>12</velocity>
        </limit>
        <dynamics>
          <damping>0.1</damping>
        </dynamics>
      </axis>
      <physics>
        <ode>
          <implicit_spring_damper>1</implicit_spring_damper>
          <limit>
            <cfm>0</cfm>
            <erp>0.2</erp>
          </limit>
        </ode>
      </physics>
    </joint>
    <link name='r_lglut'>
      <pose>0 -0.089 0 0 -0 0</pose>
      <inertial>
        <pose>0.0133341 -0.0170484 -0.0312052 0 -0 0</pose>
        <mass>0.0866</mass>
        <inertia>
          <ixx>0.000691326</ixx>
          <ixy>2.24344e-05</ixy>
          <ixz>2.50508e-06</ixz>
          <iyy>0.00126856</iyy>
          <iyz>-0.000137862</iyz>
          <izz>0.00106487</izz>
        </inertia>
      </inertial>
      <visual name='r_lglut_visual'>
        <pose>0 0 0 0 -0 0</pose>
        <geometry>
          <mesh>
            <scale>1 1 1</scale>
            <uri>model://atlas_hydra/meshes/r_lglut.DAE</uri>
          </mesh>
        </geometry>
      </visual>
      <gravity>1</gravity>
      <velocity_decay>
        <linear>0</linear>
        <angular>0</angular>
      </velocity_decay>
      <self_collide>0</self_collide>
    </link>
    <joint name='r_leg_hpx' type='revolute'>
      <child>r_lglut</child>
      <parent>r_uglut</parent>
      <axis>
        <xyz>1 0 0</xyz>
        <limit>
          <lower>0</lower>
          <upper>0</upper>
          <effort>180</effort>
          <velocity>12</velocity>
        </limit>
        <dynamics>
          <damping>0.1</damping>
        </dynamics>
      </axis>
      <physics>
        <ode>
          <implicit_spring_damper>1</implicit_spring_damper>
          <limit>
            <cfm>0</cfm>
            <erp>0.2</erp>
          </limit>
        </ode>
      </physics>
    </joint>
    <link name='r_uleg'>
      <pose>0.05 -0.089 -0.05 0 -0 0</pose>
      <inertial>
        <pose>0 0 -0.21 0 -0 0</pose>
        <mass>.9209</mass>
        <inertia>
          <ixx>0.09</ixx>
          <ixy>0</ixy>
          <ixz>0</ixz>
          <iyy>0.09</iyy>
          <iyz>0</iyz>
          <izz>0.02</izz>
        </inertia>
      </inertial>
      <visual name='r_uleg_visual'>
        <pose>0 0 0 0 -0 0</pose>
        <geometry>
          <mesh>
            <scale>1 1 1</scale>
            <uri>model://atlas_hydra/meshes/r_uleg.DAE</uri>
          </mesh>
        </geometry>
      </visual>
      <gravity>1</gravity>
      <velocity_decay>
        <linear>0</linear>
        <angular>0</angular>
      </velocity_decay>
      <self_collide>0</self_collide>
    </link>
    <joint name='r_leg_hpy' type='revolute'>
      <child>r_uleg</child>
      <parent>r_lglut</parent>
      <axis>
        <xyz>0 1 0</xyz>
        <limit>
          <lower>0</lower>
          <upper>0</upper>
          <effort>260</effort>
          <velocity>12</velocity>
        </limit>
        <dynamics>
          <damping>0.1</damping>
        </dynamics>
      </axis>
      <physics>
        <ode>
          <implicit_spring_damper>1</implicit_spring_damper>
          <limit>
            <cfm>0</cfm>
            <erp>0.2</erp>
          </limit>
        </ode>
      </physics>
    </joint>
    <link name='r_lleg'>
      <pose>0 -0.089 -0.424 0 -0 0</pose>
      <inertial>
        <pose>0.001 0 -0.187 0 -0 0</pose>
        <mass>.5479</mass>
        <inertia>
          <ixx>0.077</ixx>
          <ixy>-0</ixy>
          <ixz>-0.003</ixz>
          <iyy>0.076</iyy>
          <iyz>-0</iyz>
          <izz>0.01</izz>
        </inertia>
      </inertial>
      <visual name='r_lleg_visual'>
        <pose>0 0 0 0 -0 0</pose>
        <geometry>
          <mesh>
            <scale>1 1 1</scale>
            <uri>model://atlas_hydra/meshes/r_lleg.DAE</uri>
          </mesh>
        </geometry>
      </visual>
      <gravity>1</gravity>
      <velocity_decay>
        <linear>0</linear>
        <angular>0</angular>
      </velocity_decay>
      <self_collide>0</self_collide>
    </link>
    <joint name='r_leg_kny' type='revolute'>
      <child>r_lleg</child>
      <parent>r_uleg</parent>
      <axis>
        <xyz>0 1 0</xyz>
        <limit>
          <lower>0</lower>
          <upper>0</upper>
          <effort>220</effort>
          <velocity>12</velocity>
        </limit>
        <dynamics>
          <damping>0.1</damping>
        </dynamics>
      </axis>
      <physics>
        <ode>
          <implicit_spring_damper>1</implicit_spring_damper>
          <limit>
            <cfm>0</cfm>
            <erp>0.2</erp>
          </limit>
        </ode>
      </physics>
    </joint>
    <link name='r_talus'>
      <pose>0 -0.089 -0.846 0 -0 0</pose>
      <inertial>
        <pose>0 0 0 0 -0 0</pose>
        <mass>0.0125</mass>
        <inertia>
          <ixx>1.01674e-05</ixx>
          <ixy>0</ixy>
          <ixz>0</ixz>
          <iyy>8.42775e-06</iyy>
          <iyz>0</iyz>
          <izz>1.30101e-05</izz>
        </inertia>
      </inertial>
      <visual name='r_talus_visual'>
        <pose>0 0 0 0 -0 0</pose>
        <geometry>
          <mesh>
            <scale>1 1 1</scale>
            <uri>model://atlas_hydra/meshes/r_talus.DAE</uri>
          </mesh>
        </geometry>
      </visual>
      <gravity>1</gravity>
      <velocity_decay>
        <linear>0</linear>
        <angular>0</angular>
      </velocity_decay>
      <self_collide>0</self_collide>
    </link>
    <joint name='r_leg_aky' type='revolute'>
      <child>r_talus</child>
      <parent>r_lleg</parent>
      <axis>
        <xyz>0 1 0</xyz>
        <limit>
          <lower>0</lower>
          <upper>0</upper>
          <effort>700</effort>
          <velocity>12</velocity>
        </limit>
        <dynamics>
          <damping>0.1</damping>
        </dynamics>
      </axis>
      <physics>
        <ode>
          <implicit_spring_damper>1</implicit_spring_damper>
          <limit>
            <cfm>0</cfm>
            <erp>0.2</erp>
          </limit>
        </ode>
      </physics>
    </joint>
    <link name='r_foot'>
      <pose>0 -0.089 -0.846 0 -0 0</pose>
      <inertial>
        <pose>0.027 0 -0.067 0 -0 0</pose>
        <mass>.205</mass>
        <inertia>
          <ixx>0.002</ixx>
          <ixy>0</ixy>
          <ixz>0</ixz>
          <iyy>0.007</iyy>
          <iyz>0</iyz>
          <izz>0.008</izz>
        </inertia>
      </inertial>
      <collision name='r_foot_collision'>
        <pose>0 0 0 0 -0 0</pose>
        <geometry>
          <mesh>
            <scale>1 1 1</scale>
            <uri>model://atlas_hydra/meshes/r_foot.DAE</uri>
          </mesh>
        </geometry>
        <surface>
          <contact>
            <ode>
              <kp>1e+06</kp>
              <kd>100</kd>
              <max_vel>1</max_vel>
              <min_depth>0</min_depth>
            </ode>
          </contact>
          <friction>
            <ode>
              <mu>0.1</mu>
              <mu2>0.1</mu2>
              <fdir1>1 0 0</fdir1>
            </ode>
          </friction>
        </surface>
      </collision>
      <visual name='r_foot_visual'>
        <pose>0 0 0 0 -0 0</pose>
        <geometry>
          <mesh>
            <scale>1 1 1</scale>
            <uri>model://atlas_hydra/meshes/r_foot.DAE</uri>
          </mesh>
        </geometry>
      </visual>
    </link>
    <joint name='r_leg_akx' type='revolute'>
      <child>r_foot</child>
      <parent>r_talus</parent>
      <axis>
        <xyz>1 0 0</xyz>
        <limit>
          <lower>0</lower>
          <upper>0</upper>
          <effort>90</effort>
          <velocity>12</velocity>
        </limit>
        <dynamics>
          <damping>0.1</damping>
        </dynamics>
      </axis>
      <physics>
        <provide_feedback>1</provide_feedback>
        <ode>
          <provide_feedback>1</provide_feedback>
          <implicit_spring_damper>1</implicit_spring_damper>
          <limit>
            <cfm>0</cfm>
            <erp>0.2</erp>
          </limit>
        </ode>
      </physics>
    </joint>
-->
    <pose>0 0 0.93 0 -0 0</pose>

    <plugin name='teleop_atlas_plugin' filename='libTeleopAtlasPlugin.so'>
      <pin_model>dolly</pin_model>
      <pin_link>link</pin_link>
    </plugin>

    <plugin name='right_ik' filename='libSimpleIKPlugin.so'>
      <base_link>pelvis</base_link>
      <joint>r_arm_shy</joint>
      <joint>r_arm_shx</joint>
      <joint>r_arm_ely</joint>
      <joint>r_arm_elx</joint>
      <joint>r_arm_wry</joint>
      <joint>r_arm_wrx</joint>
      <ef_pos>0 -0.211 0.02</ef_pos>
      <goal_model>right_arm_goal_link</goal_model>
    </plugin>

    <plugin name='left_ik' filename='libSimpleIKPlugin.so'>
      <base_link>pelvis</base_link>
      <joint>l_arm_shy</joint>
      <joint>l_arm_shx</joint>
      <joint>l_arm_ely</joint>
      <joint>l_arm_elx</joint>
      <joint>l_arm_wry</joint>
      <joint>l_arm_wrx</joint>
      <ef_pos>0 0.211 0.02</ef_pos>
      <goal_model>left_arm_goal_link</goal_model>
    </plugin>

    <link name="right_arm_goal_link">
      <gravity>false</gravity>
      <pose>0.013 -.294 -0.322 1.5707 0 3.1415</pose>
      <!--
      <visual name="visual">
        <geometry>
          <box><size>.1 .1 0.1</size></box>
        </geometry>
      </visual>
-->
    </link>

    <link name="left_arm_goal_link">
      <gravity>false</gravity>
      <pose>0.013 .294 -0.322 -1.5707 0 -3.1415</pose>
      <!--
      <visual name="visual">
        <geometry>
          <box><size>.1 .1 0.1</size></box>
        </geometry>
      </visual>
-->
    </link>

  </model>
</sdf>
