<?xml version='1.0'?>
<sdf version='1.4'>
  <model name='atlas'>
    <link name='head'>
      <pose>0 0 0 0 -0 0</pose>
      <inertial>
        <pose>-0.0754942 3.38765e-05 0.0277411 0 -0 0</pose>
        <mass>1.41991</mass>
        <inertia>
          <ixx>0.00361284</ixx>
          <ixy>-1.51324e-06</ixy>
          <ixz>-0.000892818</ixz>
          <iyy>0.00208745</iyy>
          <iyz>-6.83342e-07</iyz>
          <izz>0.00179047</izz>
        </inertia>
      </inertial>
      <collision name='head_collision'>
        <pose>-0.0503 0 -0.00195 0 -0 0</pose>
        <geometry>
          <box>
            <size>0.1311 0.12 0.0591</size>
          </box>
        </geometry>
        <surface>
          <contact>
            <ode/>
          </contact>
          <friction>
            <ode>
              <mu>0.9</mu>
              <mu2>0.9</mu2>
            </ode>
          </friction>
        </surface>
      </collision>
      <collision name='head_collision_head_other'>
        <pose>-0.093 0 0.0868 0 -0 0</pose>
        <geometry>
          <box>
            <size>0.0468 0.12 0.1184</size>
          </box>
        </geometry>
        <surface>
          <contact>
            <ode/>
          </contact>
          <friction>
            <ode>
              <mu>0.9</mu>
              <mu2>0.9</mu2>
            </ode>
          </friction>
        </surface>
      </collision>
      <visual name='head_visual'>
        <pose>0 0 0 0 -0 0</pose>
        <geometry>
          <mesh>
            <scale>1 1 1</scale>
            <uri>model://multisense_sl/meshes/head.dae</uri>
          </mesh>
        </geometry>
      </visual>
      <visual name='head_visual_head_imu_link'>
        <pose>-0.0475 0.035 0 0 -0 0</pose>
        <geometry>
          <box>
            <size>0.01 0.01 0.01</size>
          </box>
        </geometry>
      </visual>
      <velocity_decay>
        <linear>0</linear>
        <angular>0</angular>
      </velocity_decay>
      <velocity_decay>
        <linear>0</linear>
        <angular>0</angular>
      </velocity_decay>
      <sensor name='head_imu_sensor' type='imu'>
        <always_on>1</always_on>
        <update_rate>1000</update_rate>
        <imu>
          <noise>
            <type>gaussian</type>
            <rate>
              <mean>0</mean>
              <stddev>0.0002</stddev>
              <bias_mean>7.5e-06</bias_mean>
              <bias_stddev>8e-07</bias_stddev>
            </rate>
            <accel>
              <mean>0</mean>
              <stddev>0.017</stddev>
              <bias_mean>0.1</bias_mean>
              <bias_stddev>0.001</bias_stddev>
            </accel>
          </noise>
        </imu>
        <pose>-0.0475 0.035 0 0 -0 0</pose>
      </sensor>
      <gravity>1</gravity>
      <velocity_decay>
        <linear>0</linear>
        <angular>0</angular>
      </velocity_decay>
      <self_collide>0</self_collide>
      <sensor name='stereo_camera' type='multicamera'>
        <update_rate>30</update_rate>
        <camera name='left'>
          <horizontal_fov>1.39626</horizontal_fov>
          <image>
            <width>800</width>
            <height>800</height>
            <format>R8G8B8</format>
          </image>
          <clip>
            <near>0.02</near>
            <far>300</far>
          </clip>
          <noise>
            <type>gaussian</type>
            <mean>0</mean>
            <stddev>0.007</stddev>
          </noise>
        </camera>
        <camera name='right'>
          <pose>0 -0.07 0 0 -0 0</pose>
          <horizontal_fov>1.39626</horizontal_fov>
          <image>
            <width>800</width>
            <height>800</height>
            <format>R8G8B8</format>
          </image>
          <clip>
            <near>0.02</near>
            <far>300</far>
          </clip>
          <noise>
            <type>gaussian</type>
            <mean>0</mean>
            <stddev>0.007</stddev>
          </noise>
        </camera>
        <!--
        <plugin name='stereo_camera' filename='libMulticamera.so'>
          <alwaysOn>true</alwaysOn>
          <updateRate>0.0</updateRate>
          <cameraName>multisense_sl/camera</cameraName>
          <imageTopicName>image_raw</imageTopicName>
          <cameraInfoTopicName>camera_info</cameraInfoTopicName>
          <frameName>left_camera_optical_frame</frameName>
          <hackBaseline>0.07</hackBaseline>
          <distortionK1>0.0</distortionK1>
          <distortionK2>0.0</distortionK2>
          <distortionK3>0.0</distortionK3>
          <distortionT1>0.0</distortionT1>
          <distortionT2>0.0</distortionT2>
        </plugin>
-->
        <pose>0 0.035 -0.002 0 -0 0</pose>
      </sensor>
    </link>
    <link name='hokuyo_link'>
      <pose>-0.0446 0 0.088 0 -0 0</pose>
      <inertial>
        <pose>0.0124384 0.0004084 -0.0041783 0 -0 0</pose>
        <mass>0.057664</mass>
        <inertia>
          <ixx>0.000401606</ixx>
          <ixy>4.9927e-08</ixy>
          <ixz>1.0997e-05</ixz>
          <iyy>0.00208115</iyy>
          <iyz>-9.8165e-09</iyz>
          <izz>0.00178402</izz>
        </inertia>
      </inertial>
      <collision name='hokuyo_link_collision'>
        <pose>0.01885 0 -0.02119 0 -0 0</pose>
        <geometry>
          <box>
            <size>0.08 0.06 0.04238</size>
          </box>
        </geometry>
        <surface>
          <contact>
            <ode/>
          </contact>
          <friction>
            <ode>
              <mu>0.9</mu>
              <mu2>0.9</mu2>
            </ode>
          </friction>
        </surface>
      </collision>
      <collision name='hokuyo_link_collision_hokuyo_link_other'>
        <pose>0.03 0 0.0235 0 -0 0</pose>
        <geometry>
          <cylinder>
            <length>0.047</length>
            <radius>0.024425</radius>
          </cylinder>
        </geometry>
        <surface>
          <contact>
            <ode/>
          </contact>
          <friction>
            <ode>
              <mu>0.9</mu>
              <mu2>0.9</mu2>
            </ode>
          </friction>
        </surface>
      </collision>
      <visual name='hokuyo_link_visual'>
        <pose>0.045 -0.0261018 -0.0834237 -0.314 0 0</pose>
        <geometry>
          <mesh>
            <scale>1 1 1</scale>
            <uri>model://multisense_sl/meshes/head_camera.dae</uri>
          </mesh>
        </geometry>
      </visual>
      <velocity_decay>
        <linear>0</linear>
        <angular>0</angular>
      </velocity_decay>
      <gravity>1</gravity>
      <velocity_decay>
        <linear>0</linear>
        <angular>0</angular>
      </velocity_decay>
      <self_collide>0</self_collide>
      <sensor name='head_hokuyo_sensor' type='gpu_ray'>
        <visualize>0</visualize>
        <update_rate>40</update_rate>
        <ray>
          <scan>
            <horizontal>
              <samples>720</samples>
              <resolution>1</resolution>
              <min_angle>-1.5708</min_angle>
              <max_angle>1.5708</max_angle>
            </horizontal>
          </scan>
          <range>
            <min>0.1</min>
            <max>30</max>
            <resolution>0.01</resolution>
          </range>
          <noise>
            <type>gaussian</type>
            <mean>0</mean>
            <stddev>0.01</stddev>
          </noise>
        </ray>
        <!--
        <plugin name='head_hokuyo' filename='libGpuRayPlugin.so'>
          <topicName>/multisense_sl/laser/scan</topicName>
        </plugin> -->
        <pose>0.03 0 0.015 0 -0 0</pose>
      </sensor>
    </link>
    <joint name='hokuyo_joint' type='revolute'>
      <child>hokuyo_link</child>
      <parent>head</parent>
      <axis>
        <xyz>1 0 0</xyz>
        <limit>
          <lower>-1e+16</lower>
          <upper>1e+16</upper>
        </limit>
        <dynamics>
          <damping>0.01</damping>
        </dynamics>
      </axis>
    </joint>
    <static>0</static>

    <!--<plugin name='multisense_plugin' filename='libMultiSenseSLPlugin.so'/>-->
  </model>
</sdf>
